Workbook

Sheet PROY. INTER
A2: INSTITUCIÓN: | C2: UNIDAD EDUCATIVA EMILIO ISAIAS ABIHANNA | AB2: INSTITUCIÓN: | AD2: =C2 -> UNIDAD EDUCATIVA EMILIO ISAIAS ABIHANNA | BC2: INSTITUCIÓN: | BE2: =AD2 -> UNIDAD EDUCATIVA EMILIO ISAIAS ABIHANNA
A3: DOCENTE TUTOR: | C3: Stalin Ochoa | AB3: DOCENTE TUTOR: | AD3: =C3 -> Stalin Ochoa | BC3: DOCENTE TUTOR: | BE3: =C3 -> Stalin Ochoa
A4: GRADO: | C4: 1ERO TECNICO | D4: PARALELO: | G4: B | AB4: GRADO: | AD4: =C4 -> 1ERO TECNICO | AE4: PARALELO: | AH4: =G4 -> B | BC4: GRADO: | BE4: =C4 -> 1ERO TECNICO | BF4: PARALELO: | BI4: =G4 -> B
A6: CALIFICACION DEL PROYECTO INTERDISCIPLINARIO | AB6: CALIFICACION DEL PROYECTO INTERDISCIPLINARIO | BC6: CALIFICACION DEL PROYECTO INTERDISCIPLINARIO
A7: FASE 1 | AB7: FASE 2 | BC7: FASE 3
A8: ESTUDIANTES | D8: MATERIAS QUE INTERVIENEN | S8: TOTAL PROYECTO | T8: PROYECTO INTERDISCIPLINARIO TOTAL 10% | U8: PROYECTO INTERDISCIPLINARIO | V8: 0.05 | W8: TOTAL TRIMESTRAL FASE 1 | X8: TOTAL TRIMESTRE (15%) | AB8: ESTUDIANTES | AE8: MATERIAS QUE INTERVIENEN | AT8: TOTAL PROYECTO | AU8: PROYECTO INTERDISCIPLINARIO TOTAL 10% | AV8: PROYECTO INTERDISCIPLINARIO | AW8: 0.05 | AX8: TOTAL TRIMESTRAL FASE 2 | AY8: TOTAL TRIMESTRE (15%) | BC8: ESTUDIANTES | BF8: MATERIAS QUE INTERVIENEN | BU8: TOTAL PROYECTO | BV8: PROYECTO INTERDISCIPLINARIO TOTAL 10% | BW8: PROYECTO INTERDISCIPLINARIO | BX8: 0.05 | BY8: TOTAL TRIMESTRAL FASE 3 | BZ8: TOTAL TRIMESTRE (15%)
A11: Nº | B11: CÉDULA | C11: APELLIDOS/NOMBRES | D11: LENGUAJE | E11: MATEMATICA | F11: INGLES | G11: QUIMICA | H11: FISICA | I11: ED. FISICA | J11: CONTABILIDAD GENERAL | K11: BIOLOGIA | L11: HISTORIOA | M11: E.C.A | N11: FILOSOFIA | O11: EMP. Y GESTION | P11: EDUCACION PARA LA CIUDADANIA | Q11: PAQUETES CONTABLES | R11: TRIBUTACION | AB11: Nº | AC11: CÉDULA | AD11: APELLIDOS/NOMBRES | AE11: LENGUAJE | AF11: MATEMATICA | AG11: INGLES | AH11: QUIMICA | AI11: FISICA | AJ11: ED. FISICA | AK11: CONTABILIDAD GENERAL | AL11: BIOLOGIA | AM11: HISTORIOA | AN11: E.C.A | AO11: FILOSOFIA | AP11: EMP. Y GESTION | AQ11: EDUCACION PARA LA CIUDADANIA | AR11: PAQUETES CONTABLES | AS11: TRIBUTACION | BC11: Nº | BD11: CÉDULA | BE11: APELLIDOS/NOMBRES | BF11: LENGUAJE | BG11: MATEMATICA | BH11: INGLES | BI11: QUIMICA | BJ11: FISICA | BK11: ED. FISICA | BL11: CONTABILIDAD GENERAL | BM11: BIOLOGIA | BN11: HISTORIOA | BO11: E.C.A | BP11: FILOSOFIA | BQ11: EMP. Y GESTION | BR11: EDUCACION PARA LA CIUDADANIA | BS11: PAQUETES CONTABLES | BT11: TRIBUTACION
A12: 1 | C12: Almeida Alvarado Ariana Guisela | D12: 10 | E12: 10 | F12: 10 | O12: 10 | S12: =AVERAGE(D12:R12) -> 10 | T12: =IFERROR(TRUNC(AVERAGE(D12:S12),2),"")*10/100 -> 1 | U12: =S12 -> 10 | V12: =U12*5/100 -> 0.5 | W12: =ROUND(X12*100/15,2) -> 10 | X12: =IFERROR(TRUNC(SUM(T12+V12),2),"") -> 1.5 | AB12: 1 | AC12: =B12 | AD12: =C12 -> Almeida Alvarado Ariana Guisela | AF12: 10 | AI12: 10 | AK12: 10 | AM12: 10 | AO12: 10 | AT12: =AVERAGE(AE12:AS12) -> 10 | AU12: =IFERROR(TRUNC(AVERAGE(AE12:AT12),2),"")*10/100 -> 1 | AV12: =AT12 -> 10 | AW12: =AV12*5/100 -> 0.5 | AX12: =ROUND(AY12*100/15,2) -> 10 | AY12: =IFERROR(TRUNC(SUM(AU12+AW12),2),"") -> 1.5 | BC12: 1 | BD12: =B12 | BE12: =C12 -> Almeida Alvarado Ariana Guisela | BU12: =AVERAGE(BF12:BT12) -> #DIV/0! | BV12: =IFERROR(TRUNC(AVERAGE(BF12:BU12),2),"")*10/100 -> 0 | BW12: =BU12 -> #DIV/0! | BX12: =BW12*5/100 -> #DIV/0! | BY12: =ROUND(BZ12*100/15,2) -> 0 | BZ12: =IFERROR(TRUNC(SUM(BV12+BX12),2),"")
A13: 2 | C13: Alvarado Vargas Dacmar Alejandra | D13: 10 | E13: 10 | F13: 10 | O13: 10 | S13: =AVERAGE(D13:Q13) -> 10 | T13: =IFERROR(TRUNC(AVERAGE(D13:S13),2),"")*10/100 -> 1 | U13: =S13 -> 10 | V13: =U13*5/100 -> 0.5 | W13: =ROUND(X13*100/15,2) -> 10 | X13: =IFERROR(TRUNC(SUM(T13+V13),2),"") -> 1.5 | AB13: 2 | AC13: =B13 | AD13: =C13 -> Alvarado Vargas Dacmar Alejandra | AF13: 10 | AI13: 10 | AK13: 10 | AM13: 10 | AO13: 10 | AT13: =AVERAGE(AE13:AS13) -> 10 | AU13: =IFERROR(TRUNC(AVERAGE(AE13:AT13),2),"")*10/100 -> 1 | AV13: =AT13 -> 10 | AW13: =AV13*5/100 -> 0.5 | AX13: =ROUND(AY13*100/15,2) -> 10 | AY13: =IFERROR(TRUNC(SUM(AU13+AW13),2),"") -> 1.5 | BC13: 2 | BD13: =B13 | BE13: =C13 -> Alvarado Vargas Dacmar Alejandra | BU13: =AVERAGE(BF13:BT13) -> #DIV/0! | BV13: =IFERROR(TRUNC(AVERAGE(BF13:BU13),2),"")*10/100 -> 0 | BW13: =BU13 -> #DIV/0! | BX13: =BW13*5/100 -> #DIV/0! | BY13: =ROUND(BZ13*100/15,2) -> 0 | BZ13: =IFERROR(TRUNC(SUM(BV13+BX13),2),"")
A14: 3 | C14: Ampuero Cornejo Cesar Jeanpierre | D14: 10 | E14: 10 | F14: 8 | O14: 5 | S14: =AVERAGE(D14:Q14) -> 8.25 | T14: =IFERROR(TRUNC(AVERAGE(D14:S14),2),"")*10/100 -> 0.825 | U14: =S14 -> 8.25 | V14: =U14*5/100 -> 0.4125 | W14: =ROUND(X14*100/15,2) -> 8.2 | X14: =IFERROR(TRUNC(SUM(T14+V14),2),"") -> 1.23 | AB14: 3 | AC14: =B14 | AD14: =C14 -> Ampuero Cornejo Cesar Jeanpierre | AF14: 10 | AI14: 10 | AK14: 10 | AM14: 10 | AO14: 10 | AT14: =AVERAGE(AE14:AS14) -> 10 | AU14: =IFERROR(TRUNC(AVERAGE(AE14:AT14),2),"")*10/100 -> 1 | AV14: =AT14 -> 10 | AW14: =AV14*5/100 -> 0.5 | AX14: =ROUND(AY14*100/15,2) -> 10 | AY14: =IFERROR(TRUNC(SUM(AU14+AW14),2),"") -> 1.5 | BC14: 3 | BD14: =B14 | BE14: =C14 -> Ampuero Cornejo Cesar Jeanpierre | BU14: =AVERAGE(BF14:BT14) -> #DIV/0! | BV14: =IFERROR(TRUNC(AVERAGE(BF14:BU14),2),"")*10/100 -> 0 | BW14: =BU14 -> #DIV/0! | BX14: =BW14*5/100 -> #DIV/0! | BY14: =ROUND(BZ14*100/15,2) -> 0 | BZ14: =IFERROR(TRUNC(SUM(BV14+BX14),2),"")
A15: 4 | C15: Aylla Murillo Kerly Kristhel | D15: 7 | E15: 10 | F15: 5 | O15: 5 | S15: =AVERAGE(D15:Q15) -> 6.75 | T15: =IFERROR(TRUNC(AVERAGE(D15:S15),2),"")*10/100 -> 0.675 | U15: =S15 -> 6.75 | V15: =U15*5/100 -> 0.3375 | W15: =ROUND(X15*100/15,2) -> 6.73 | X15: =IFERROR(TRUNC(SUM(T15+V15),2),"") -> 1.01 | AB15: 4 | AC15: =B15 | AD15: =C15 -> Aylla Murillo Kerly Kristhel | AF15: 10 | AI15: 10 | AK15: 10 | AM15: 10 | AO15: 10 | AT15: =AVERAGE(AE15:AS15) -> 10 | AU15: =IFERROR(TRUNC(AVERAGE(AE15:AT15),2),"")*10/100 -> 1 | AV15: =AT15 -> 10 | AW15: =AV15*5/100 -> 0.5 | AX15: =ROUND(AY15*100/15,2) -> 10 | AY15: =IFERROR(TRUNC(SUM(AU15+AW15),2),"") -> 1.5 | BC15: 4 | BD15: =B15 | BE15: =C15 -> Aylla Murillo Kerly Kristhel | BU15: =AVERAGE(BF15:BT15) -> #DIV/0! | BV15: =IFERROR(TRUNC(AVERAGE(BF15:BU15),2),"")*10/100 -> 0 | BW15: =BU15 -> #DIV/0! | BX15: =BW15*5/100 -> #DIV/0! | BY15: =ROUND(BZ15*100/15,2) -> 0 | BZ15: =IFERROR(TRUNC(SUM(BV15+BX15),2),"")
A16: 5 | C16: Campuzano Meza Naydelyn Odeth | D16: 7 | E16: 10 | F16: 2 | O16: 5 | S16: =AVERAGE(D16:Q16) -> 6 | T16: =IFERROR(TRUNC(AVERAGE(D16:S16),2),"")*10/100 -> 0.6 | U16: =S16 -> 6 | V16: =U16*5/100 -> 0.3 | W16: =ROUND(X16*100/15,2) -> 6 | X16: =IFERROR(TRUNC(SUM(T16+V16),2),"") -> 0.9 | AB16: 5 | AC16: =B16 | AD16: =C16 -> Campuzano Meza Naydelyn Odeth | AF16: 2 | AI16: 2 | AK16: 2 | AM16: 2 | AO16: 2 | AT16: =AVERAGE(AE16:AS16) -> 2 | AU16: =IFERROR(TRUNC(AVERAGE(AE16:AT16),2),"")*10/100 -> 0.2 | AV16: =AT16 -> 2 | AW16: =AV16*5/100 -> 0.1 | AX16: =ROUND(AY16*100/15,2) -> 2 | AY16: =IFERROR(TRUNC(SUM(AU16+AW16),2),"") -> 0.3 | BC16: 5 | BD16: =B16 | BE16: =C16 -> Campuzano Meza Naydelyn Odeth | BU16: =AVERAGE(BF16:BT16) -> #DIV/0! | BV16: =IFERROR(TRUNC(AVERAGE(BF16:BU16),2),"")*10/100 -> 0 | BW16: =BU16 -> #DIV/0! | BX16: =BW16*5/100 -> #DIV/0! | BY16: =ROUND(BZ16*100/15,2) -> 0 | BZ16: =IFERROR(TRUNC(SUM(BV16+BX16),2),"")
A17: 6 | C17: Cantos Zúñiga a Hernán Snayder | D17: 10 | E17: 10 | F17: 9.5 | O17: 10 | S17: =AVERAGE(D17:Q17) -> 9.875 | T17: =IFERROR(TRUNC(AVERAGE(D17:S17),2),"")*10/100 -> 0.987 | U17: =S17 -> 9.875 | V17: =U17*5/100 -> 0.49375 | W17: =ROUND(X17*100/15,2) -> 9.87 | X17: =IFERROR(TRUNC(SUM(T17+V17),2),"") -> 1.48 | AB17: 6 | AC17: =B17 | AD17: =C17 -> Cantos Zúñiga a Hernán Snayder | AF17: 10 | AI17: 10 | AK17: 10 | AM17: 10 | AO17: 10 | AT17: =AVERAGE(AE17:AS17) -> 10 | AU17: =IFERROR(TRUNC(AVERAGE(AE17:AT17),2),"")*10/100 -> 1 | AV17: =AT17 -> 10 | AW17: =AV17*5/100 -> 0.5 | AX17: =ROUND(AY17*100/15,2) -> 10 | AY17: =IFERROR(TRUNC(SUM(AU17+AW17),2),"") -> 1.5 | BC17: 6 | BD17: =B17 | BE17: =C17 -> Cantos Zúñiga a Hernán Snayder | BU17: =AVERAGE(BF17:BT17) -> #DIV/0! | BV17: =IFERROR(TRUNC(AVERAGE(BF17:BU17),2),"")*10/100 -> 0 | BW17: =BU17 -> #DIV/0! | BX17: =BW17*5/100 -> #DIV/0! | BY17: =ROUND(BZ17*100/15,2) -> 0 | BZ17: =IFERROR(TRUNC(SUM(BV17+BX17),2),"")
A18: 7 | C18: Carranza Dumes Genesis Daniela | D18: 10 | E18: 10 | F18: 8 | O18: 8 | S18: =AVERAGE(D18:Q18) -> 9 | T18: =IFERROR(TRUNC(AVERAGE(D18:S18),2),"")*10/100 -> 0.9 | U18: =S18 -> 9 | V18: =U18*5/100 -> 0.45 | W18: =ROUND(X18*100/15,2) -> 9 | X18: =IFERROR(TRUNC(SUM(T18+V18),2),"") -> 1.35 | AB18: 7 | AC18: =B18 | AD18: =C18 -> Carranza Dumes Genesis Daniela | AF18: 2 | AI18: 2 | AK18: 2 | AM18: 2 | AO18: 2 | AT18: =AVERAGE(AE18:AS18) -> 2 | AU18: =IFERROR(TRUNC(AVERAGE(AE18:AT18),2),"")*10/100 -> 0.2 | AV18: =AT18 -> 2 | AW18: =AV18*5/100 -> 0.1 | AX18: =ROUND(AY18*100/15,2) -> 2 | AY18: =IFERROR(TRUNC(SUM(AU18+AW18),2),"") -> 0.3 | BC18: 7 | BD18: =B18 | BE18: =C18 -> Carranza Dumes Genesis Daniela | BU18: =AVERAGE(BF18:BT18) -> #DIV/0! | BV18: =IFERROR(TRUNC(AVERAGE(BF18:BU18),2),"")*10/100 -> 0 | BW18: =BU18 -> #DIV/0! | BX18: =BW18*5/100 -> #DIV/0! | BY18: =ROUND(BZ18*100/15,2) -> 0 | BZ18: =IFERROR(TRUNC(SUM(BV18+BX18),2),"")
A19: 8 | C19: Castro De La Rosa Cristopher Ruben | D19: 7 | E19: 10 | F19: 2 | O19: 5 | S19: =AVERAGE(D19:Q19) -> 6 | T19: =IFERROR(TRUNC(AVERAGE(D19:S19),2),"")*10/100 -> 0.6 | U19: =S19 -> 6 | V19: =U19*5/100 -> 0.3 | W19: =ROUND(X19*100/15,2) -> 6 | X19: =IFERROR(TRUNC(SUM(T19+V19),2),"") -> 0.9 | AB19: 8 | AC19: =B19 | AD19: =C19 -> Castro De La Rosa Cristopher Ruben | AF19: 2 | AI19: 2 | AK19: 2 | AM19: 2 | AO19: 2 | AT19: =AVERAGE(AE19:AS19) -> 2 | AU19: =IFERROR(TRUNC(AVERAGE(AE19:AT19),2),"")*10/100 -> 0.2 | AV19: =AT19 -> 2 | AW19: =AV19*5/100 -> 0.1 | AX19: =ROUND(AY19*100/15,2) -> 2 | AY19: =IFERROR(TRUNC(SUM(AU19+AW19),2),"") -> 0.3 | BC19: 8 | BD19: =B19 | BE19: =C19 -> Castro De La Rosa Cristopher Ruben | BU19: =AVERAGE(BF19:BT19) -> #DIV/0! | BV19: =IFERROR(TRUNC(AVERAGE(BF19:BU19),2),"")*10/100 -> 0 | BW19: =BU19 -> #DIV/0! | BX19: =BW19*5/100 -> #DIV/0! | BY19: =ROUND(BZ19*100/15,2) -> 0 | BZ19: =IFERROR(TRUNC(SUM(BV19+BX19),2),"")
A20: 9 | C20: Chamba Maurad Joshelyn Juleixi | D20: 7 | E20: 10 | F20: 2 | O20: 5 | S20: =AVERAGE(D20:Q20) -> 6 | T20: =IFERROR(TRUNC(AVERAGE(D20:S20),2),"")*10/100 -> 0.6 | U20: =S20 -> 6 | V20: =U20*5/100 -> 0.3 | W20: =ROUND(X20*100/15,2) -> 6 | X20: =IFERROR(TRUNC(SUM(T20+V20),2),"") -> 0.9 | AB20: 9 | AC20: =B20 | AD20: =C20 -> Chamba Maurad Joshelyn Juleixi | AF20: 10 | AI20: 10 | AK20: 10 | AM20: 10 | AO20: 10 | AT20: =AVERAGE(AE20:AS20) -> 10 | AU20: =IFERROR(TRUNC(AVERAGE(AE20:AT20),2),"")*10/100 -> 1 | AV20: =AT20 -> 10 | AW20: =AV20*5/100 -> 0.5 | AX20: =ROUND(AY20*100/15,2) -> 10 | AY20: =IFERROR(TRUNC(SUM(AU20+AW20),2),"") -> 1.5 | BC20: 9 | BD20: =B20 | BE20: =C20 -> Chamba Maurad Joshelyn Juleixi | BU20: =AVERAGE(BF20:BT20) -> #DIV/0! | BV20: =IFERROR(TRUNC(AVERAGE(BF20:BU20),2),"")*10/100 -> 0 | BW20: =BU20 -> #DIV/0! | BX20: =BW20*5/100 -> #DIV/0! | BY20: =ROUND(BZ20*100/15,2) -> 0 | BZ20: =IFERROR(TRUNC(SUM(BV20+BX20),2),"")
A21: 10 | C21: Cedeño Sanchez Josué | D21: 7 | E21: 10 | F21: 2 | O21: 5 | S21: =AVERAGE(D21:Q21) -> 6 | T21: =IFERROR(TRUNC(AVERAGE(D21:S21),2),"")*10/100 -> 0.6 | U21: =S21 -> 6 | V21: =U21*5/100 -> 0.3 | W21: =ROUND(X21*100/15,2) -> 6 | X21: =IFERROR(TRUNC(SUM(T21+V21),2),"") -> 0.9 | AB21: 10 | AC21: =B21 | AD21: =C21 -> Cedeño Sanchez Josué | AF21: 2 | AI21: 2 | AK21: 2 | AM21: 2 | AO21: 2 | AT21: =AVERAGE(AE21:AS21) -> 2 | AU21: =IFERROR(TRUNC(AVERAGE(AE21:AT21),2),"")*10/100 -> 0.2 | AV21: =AT21 -> 2 | AW21: =AV21*5/100 -> 0.1 | AX21: =ROUND(AY21*100/15,2) -> 2 | AY21: =IFERROR(TRUNC(SUM(AU21+AW21),2),"") -> 0.3 | BC21: 10 | BD21: =B21 | BE21: =C21 -> Cedeño Sanchez Josué | BU21: =AVERAGE(BF21:BT21) -> #DIV/0! | BV21: =IFERROR(TRUNC(AVERAGE(BF21:BU21),2),"")*10/100 -> 0 | BW21: =BU21 -> #DIV/0! | BX21: =BW21*5/100 -> #DIV/0! | BY21: =ROUND(BZ21*100/15,2) -> 0 | BZ21: =IFERROR(TRUNC(SUM(BV21+BX21),2),"")
A22: 11 | C22: Espinoza Martinez Stefano Juliano | D22: 10 | E22: 10 | F22: 10 | O22: 10 | S22: =AVERAGE(D22:Q22) -> 10 | T22: =IFERROR(TRUNC(AVERAGE(D22:S22),2),"")*10/100 -> 1 | U22: =S22 -> 10 | V22: =U22*5/100 -> 0.5 | W22: =ROUND(X22*100/15,2) -> 10 | X22: =IFERROR(TRUNC(SUM(T22+V22),2),"") -> 1.5 | AB22: 11 | AC22: =B22 | AD22: =C22 -> Espinoza Martinez Stefano Juliano | AF22: 10 | AI22: 10 | AK22: 10 | AM22: 10 | AO22: 10 | AT22: =AVERAGE(AE22:AS22) -> 10 | AU22: =IFERROR(TRUNC(AVERAGE(AE22:AT22),2),"")*10/100 -> 1 | AV22: =AT22 -> 10 | AW22: =AV22*5/100 -> 0.5 | AX22: =ROUND(AY22*100/15,2) -> 10 | AY22: =IFERROR(TRUNC(SUM(AU22+AW22),2),"") -> 1.5 | BC22: 11 | BD22: =B22 | BE22: =C22 -> Espinoza Martinez Stefano Juliano | BU22: =AVERAGE(BF22:BT22) -> #DIV/0! | BV22: =IFERROR(TRUNC(AVERAGE(BF22:BU22),2),"")*10/100 -> 0 | BW22: =BU22 -> #DIV/0! | BX22: =BW22*5/100 -> #DIV/0! | BY22: =ROUND(BZ22*100/15,2) -> 0 | BZ22: =IFERROR(TRUNC(SUM(BV22+BX22),2),"")
A23: 12 | C23: Espinoza Morante Melany Ginger | D23: 10 | E23: 10 | F23: 2 | O23: 7 | S23: =AVERAGE(D23:Q23) -> 7.25 | T23: =IFERROR(TRUNC(AVERAGE(D23:S23),2),"")*10/100 -> 0.725 | U23: =S23 -> 7.25 | V23: =U23*5/100 -> 0.3625 | W23: =ROUND(X23*100/15,2) -> 7.2 | X23: =IFERROR(TRUNC(SUM(T23+V23),2),"") -> 1.08 | AB23: 12 | AC23: =B23 | AD23: =C23 -> Espinoza Morante Melany Ginger | AF23: 10 | AI23: 10 | AK23: 10 | AM23: 10 | AO23: 10 | AT23: =AVERAGE(AE23:AS23) -> 10 | AU23: =IFERROR(TRUNC(AVERAGE(AE23:AT23),2),"")*10/100 -> 1 | AV23: =AT23 -> 10 | AW23: =AV23*5/100 -> 0.5 | AX23: =ROUND(AY23*100/15,2) -> 10 | AY23: =IFERROR(TRUNC(SUM(AU23+AW23),2),"") -> 1.5 | BC23: 12 | BD23: =B23 | BE23: =C23 -> Espinoza Morante Melany Ginger | BU23: =AVERAGE(BF23:BT23) -> #DIV/0! | BV23: =IFERROR(TRUNC(AVERAGE(BF23:BU23),2),"")*10/100 -> 0 | BW23: =BU23 -> #DIV/0! | BX23: =BW23*5/100 -> #DIV/0! | BY23: =ROUND(BZ23*100/15,2) -> 0 | BZ23: =IFERROR(TRUNC(SUM(BV23+BX23),2),"")
A24: 13 | C24: Garrido franco Génesis Lissette | D24: 10 | E24: 10 | F24: 9 | O24: 7 | S24: =AVERAGE(D24:Q24) -> 9 | T24: =IFERROR(TRUNC(AVERAGE(D24:S24),2),"")*10/100 -> 0.9 | U24: =S24 -> 9 | V24: =U24*5/100 -> 0.45 | W24: =ROUND(X24*100/15,2) -> 9 | X24: =IFERROR(TRUNC(SUM(T24+V24),2),"") -> 1.35 | AB24: 13 | AC24: =B24 | AD24: =C24 -> Garrido franco Génesis Lissette | AF24: 10 | AI24: 10 | AK24: 10 | AM24: 10 | AO24: 10 | AT24: =AVERAGE(AE24:AS24) -> 10 | AU24: =IFERROR(TRUNC(AVERAGE(AE24:AT24),2),"")*10/100 -> 1 | AV24: =AT24 -> 10 | AW24: =AV24*5/100 -> 0.5 | AX24: =ROUND(AY24*100/15,2) -> 10 | AY24: =IFERROR(TRUNC(SUM(AU24+AW24),2),"") -> 1.5 | BC24: 13 | BD24: =B24 | BE24: =C24 -> Garrido franco Génesis Lissette | BU24: =AVERAGE(BF24:BT24) -> #DIV/0! | BV24: =IFERROR(TRUNC(AVERAGE(BF24:BU24),2),"")*10/100 -> 0 | BW24: =BU24 -> #DIV/0! | BX24: =BW24*5/100 -> #DIV/0! | BY24: =ROUND(BZ24*100/15,2) -> 0 | BZ24: =IFERROR(TRUNC(SUM(BV24+BX24),2),"")
... A34: 23 | C34: Veliz chicaiza Alex isaac | D34: 7 | E34: 10 | F34: 7.5 | O34: 5 | S34: =AVERAGE(D34:Q34) -> 7.375 | T34: =IFERROR(TRUNC(AVERAGE(D34:S34),2),"")*10/100 -> 0.737 | U34: =S34 -> 7.375 | V34: =U34*5/100 -> 0.36875 | W34: =ROUND(X34*100/15,2) -> 7.33 | X34: =IFERROR(TRUNC(SUM(T34+V34),2),"") -> 1.1 | AB34: 23 | AC34: =B34 | AD34: =C34 -> Veliz chicaiza Alex isaac | AF34: 10 | AI34: 10 | AK34: 10 | AM34: 10 | AO34: 10 | AT34: =AVERAGE(AE34:AS34) -> 10 | AU34: =IFERROR(TRUNC(AVERAGE(AE34:AT34),2),"")*10/100 -> 1 | AV34: =AT34 -> 10 | AW34: =AV34*5/100 -> 0.5 | AX34: =ROUND(AY34*100/15,2) -> 10 | AY34: =IFERROR(TRUNC(SUM(AU34+AW34),2),"") -> 1.5 | BC34: 23 | BD34: =B34 | BE34: =C34 -> Veliz chicaiza Alex isaac | BU34: =AVERAGE(BF34:BT34) -> #DIV/0! | BV34: =IFERROR(TRUNC(AVERAGE(BF34:BU34),2),"")*10/100 -> 0 | BW34: =BU34 -> #DIV/0! | BX34: =BW34*5/100 -> #DIV/0! | BY34: =ROUND(BZ34*100/15,2) -> 0 | BZ34: =IFERROR(TRUNC(SUM(BV34+BX34),2),"")
A35: 24 | C35: Zambrano Zhicay Victor Humberto | D35: 10 | E35: 10 | F35: 9 | O35: 10 | S35: =AVERAGE(D35:Q35) -> 9.75 | T35: =IFERROR(TRUNC(AVERAGE(D35:S35),2),"")*10/100 -> 0.975 | U35: =S35 -> 9.75 | V35: =U35*5/100 -> 0.4875 | W35: =ROUND(X35*100/15,2) -> 9.73 | X35: =IFERROR(TRUNC(SUM(T35+V35),2),"") -> 1.46 | AB35: 24 | AC35: =B35 | AD35: =C35 -> Zambrano Zhicay Victor Humberto | AF35: 10 | AI35: 10 | AK35: 10 | AM35: 10 | AO35: 10 | AT35: =AVERAGE(AE35:AS35) -> 10 | AU35: =IFERROR(TRUNC(AVERAGE(AP35:AT35),2),"")*10/100 -> 1 | AV35: =AT35 -> 10 | AW35: =AV35*5/100 -> 0.5 | AX35: =ROUND(AY35*100/15,2) -> 10 | AY35: =IFERROR(TRUNC(SUM(AU35+AW35),2),"") -> 1.5 | BC35: 24 | BD35: =B35 | BE35: =C35 -> Zambrano Zhicay Victor Humberto | BU35: =AVERAGE(BF35:BT35) -> #DIV/0! | BV35: =IFERROR(TRUNC(AVERAGE(BF35:BU35),2),"")*10/100 -> 0 | BW35: =BU35 -> #DIV/0! | BX35: =BW35*5/100 -> #DIV/0! | BY35: =ROUND(BZ35*100/15,2) -> 0 | BZ35: =IFERROR(TRUNC(SUM(BV35+BX35),2),"")
A36: 25 | S36: =AVERAGE(D36:Q36) -> #DIV/0! | T36: =IFERROR(TRUNC(AVERAGE(D36:S36),2),"")*10/100 -> 0 | U36: =S36 -> #DIV/0! | V36: =U36*5/100 -> #DIV/0! | W36: =ROUND(X36*100/15,2) -> 0 | X36: =IFERROR(TRUNC(SUM(T36+V36),2),"") | AB36: 25 | AC36: =B36 | AD36: =C36 | AT36: =AVERAGE(AE36:AS36) -> #DIV/0! | AU36: =IFERROR(TRUNC(AVERAGE(AE36:AT36),2),"")*10/100 -> 0 | AV36: =AT36 -> #DIV/0! | AW36: =AV36*5/100 -> #DIV/0! | AX36: =ROUND(AY36*100/15,2) -> 0 | AY36: =IFERROR(TRUNC(SUM(AU36+AW36),2),"") | BC36: 25 | BD36: =B36 | BE36: =C36 | BU36: =AVERAGE(BF36:BT36) -> #DIV/0! | BV36: =IFERROR(TRUNC(AVERAGE(BF36:BU36),2),"")*10/100 -> 0 | BW36: =BU36 -> #DIV/0! | BX36: =BW36*5/100 -> #DIV/0! | BY36: =ROUND(BZ36*100/15,2) -> 0 | BZ36: =IFERROR(TRUNC(SUM(BV36+BX36),2),"")
A37: 26 | S37: =AVERAGE(D37:Q37) -> #DIV/0! | T37: =IFERROR(TRUNC(AVERAGE(D37:S37),2),"")*10/100 -> 0 | U37: =S37 -> #DIV/0! | V37: =U37*5/100 -> #DIV/0! | W37: =ROUND(X37*100/15,2) -> 0 | X37: =IFERROR(TRUNC(SUM(T37+V37),2),"") | AB37: 26 | AC37: =B37 | AD37: =C37 | AT37: =AVERAGE(AE37:AS37) -> #DIV/0! | AU37: =IFERROR(TRUNC(AVERAGE(AE37:AT37),2),"")*10/100 -> 0 | AV37: =AT37 -> #DIV/0! | AW37: =AV37*5/100 -> #DIV/0! | AX37: =ROUND(AY37*100/15,2) -> 0 | AY37: =IFERROR(TRUNC(SUM(AU37+AW37),2),"") | BC37: 26 | BD37: =B37 | BE37: =C37 | BU37: =AVERAGE(BF37:BT37) -> #DIV/0! | BV37: =IFERROR(TRUNC(AVERAGE(BF37:BU37),2),"")*10/100 -> 0 | BW37: =BU37 -> #DIV/0! | BX37: =BW37*5/100 -> #DIV/0! | BY37: =ROUND(BZ37*100/15,2) -> 0 | BZ37: =IFERROR(TRUNC(SUM(BV37+BX37),2),"")
A38: 27 | S38: =AVERAGE(D38:Q38) -> #DIV/0! | T38: =IFERROR(TRUNC(AVERAGE(D38:S38),2),"")*10/100 -> 0 | U38: =S38 -> #DIV/0! | V38: =U38*5/100 -> #DIV/0! | W38: =ROUND(X38*100/15,2) -> 0 | X38: =IFERROR(TRUNC(SUM(T38+V38),2),"") | AB38: 27 | AC38: =B38 | AD38: =C38 | AT38: =AVERAGE(AE38:AS38) -> #DIV/0! | AU38: =IFERROR(TRUNC(AVERAGE(AE38:AT38),2),"")*10/100 -> 0 | AV38: =AT38 -> #DIV/0! | AW38: =AV38*5/100 -> #DIV/0! | AX38: =ROUND(AY38*100/15,2) -> 0 | AY38: =IFERROR(TRUNC(SUM(AU38+AW38),2),"") | BC38: 27 | BD38: =B38 | BE38: =C38 | BU38: =AVERAGE(BF38:BT38) -> #DIV/0! | BV38: =IFERROR(TRUNC(AVERAGE(BF38:BU38),2),"")*10/100 -> 0 | BW38: =BU38 -> #DIV/0! | BX38: =BW38*5/100 -> #DIV/0! | BY38: =ROUND(BZ38*100/15,2) -> 0 | BZ38: =IFERROR(TRUNC(SUM(BV38+BX38),2),"")
A39: 28 | S39: =AVERAGE(D39:Q39) -> #DIV/0! | T39: =IFERROR(TRUNC(AVERAGE(D39:S39),2),"")*10/100 -> 0 | U39: =S39 -> #DIV/0! | V39: =U39*5/100 -> #DIV/0! | W39: =ROUND(X39*100/15,2) -> 0 | X39: =IFERROR(TRUNC(SUM(T39+V39),2),"") | AB39: 28 | AC39: =B39 | AD39: =C39 | AT39: =AVERAGE(AE39:AS39) -> #DIV/0! | AU39: =IFERROR(TRUNC(AVERAGE(AE39:AT39),2),"")*10/100 -> 0 | AV39: =AT39 -> #DIV/0! | AW39: =AV39*5/100 -> #DIV/0! | AX39: =ROUND(AY39*100/15,2) -> 0 | AY39: =IFERROR(TRUNC(SUM(AU39+AW39),2),"") | BC39: 28 | BD39: =B39 | BE39: =C39 | BU39: =AVERAGE(BF39:BT39) -> #DIV/0! | BV39: =IFERROR(TRUNC(AVERAGE(BF39:BU39),2),"")*10/100 -> 0 | BW39: =BU39 -> #DIV/0! | BX39: =BW39*5/100 -> #DIV/0! | BY39: =ROUND(BZ39*100/15,2) -> 0 | BZ39: =IFERROR(TRUNC(SUM(BV39+BX39),2),"")
A40: 29 | S40: =AVERAGE(D40:Q40) -> #DIV/0! | T40: =IFERROR(TRUNC(AVERAGE(D40:S40),2),"")*10/100 -> 0 | U40: =S40 -> #DIV/0! | V40: =U40*5/100 -> #DIV/0! | W40: =ROUND(X40*100/15,2) -> 0 | X40: =IFERROR(TRUNC(SUM(T40+V40),2),"") | AB40: 29 | AC40: =B40 | AD40: =C40 | AT40: =AVERAGE(AE40:AS40) -> #DIV/0! | AU40: =IFERROR(TRUNC(AVERAGE(AE40:AT40),2),"")*10/100 -> 0 | AV40: =AT40 -> #DIV/0! | AW40: =AV40*5/100 -> #DIV/0! | AX40: =ROUND(AY40*100/15,2) -> 0 | AY40: =IFERROR(TRUNC(SUM(AU40+AW40),2),"") | BC40: 29 | BD40: =B40 | BE40: =C40 | BU40: =AVERAGE(BF40:BT40) -> #DIV/0! | BV40: =IFERROR(TRUNC(AVERAGE(BF40:BU40),2),"")*10/100 -> 0 | BW40: =BU40 -> #DIV/0! | BX40: =BW40*5/100 -> #DIV/0! | BY40: =ROUND(BZ40*100/15,2) -> 0 | BZ40: =IFERROR(TRUNC(SUM(BV40+BX40),2),"")
A41: 30 | S41: =AVERAGE(D41:Q41) -> #DIV/0! | T41: =IFERROR(TRUNC(AVERAGE(D41:S41),2),"")*10/100 -> 0 | U41: =S41 -> #DIV/0! | V41: =U41*5/100 -> #DIV/0! | W41: =ROUND(X41*100/15,2) -> 0 | X41: =IFERROR(TRUNC(SUM(T41+V41),2),"") | AB41: 30 | AC41: =B41 | AD41: =C41 | AT41: =AVERAGE(AE41:AS41) -> #DIV/0! | AU41: =IFERROR(TRUNC(AVERAGE(AE41:AT41),2),"")*10/100 -> 0 | AV41: =AT41 -> #DIV/0! | AW41: =AV41*5/100 -> #DIV/0! | AX41: =ROUND(AY41*100/15,2) -> 0 | AY41: =IFERROR(TRUNC(SUM(AU41+AW41),2),"") | BC41: 30 | BD41: =B41 | BE41: =C41 | BU41: =AVERAGE(BF41:BT41) -> #DIV/0! | BV41: =IFERROR(TRUNC(AVERAGE(BF41:BU41),2),"")*10/100 -> 0 | BW41: =BU41 -> #DIV/0! | BX41: =BW41*5/100 -> #DIV/0! | BY41: =ROUND(BZ41*100/15,2) -> 0 | BZ41: =IFERROR(TRUNC(SUM(BV41+BX41),2),"")
A42: 31 | S42: =AVERAGE(D42:Q42) -> #DIV/0! | T42: =IFERROR(TRUNC(AVERAGE(D42:S42),2),"")*10/100 -> 0 | U42: =S42 -> #DIV/0! | V42: =U42*5/100 -> #DIV/0! | W42: =ROUND(X42*100/15,2) -> 0 | X42: =IFERROR(TRUNC(SUM(T42+V42),2),"") | AB42: 31 | AC42: =B42 | AD42: =C42 | AT42: =AVERAGE(AE42:AS42) -> #DIV/0! | AU42: =IFERROR(TRUNC(AVERAGE(AE42:AT42),2),"")*10/100 -> 0 | AV42: =AT42 -> #DIV/0! | AW42: =AV42*5/100 -> #DIV/0! | AX42: =ROUND(AY42*100/15,2) -> 0 | AY42: =IFERROR(TRUNC(SUM(AU42+AW42),2),"") | BC42: 31 | BD42: =B42 | BE42: =C42 | BU42: =AVERAGE(BF42:BT42) -> #DIV/0! | BV42: =IFERROR(TRUNC(AVERAGE(BF42:BU42),2),"")*10/100 -> 0 | BW42: =BU42 -> #DIV/0! | BX42: =BW42*5/100 -> #DIV/0! | BY42: =ROUND(BZ42*100/15,2) -> 0 | BZ42: =IFERROR(TRUNC(SUM(BV42+BX42),2),"")
A43: 32 | S43: =AVERAGE(D43:Q43) -> #DIV/0! | T43: =IFERROR(TRUNC(AVERAGE(D43:S43),2),"")*10/100 -> 0 | U43: =S43 -> #DIV/0! | V43: =U43*5/100 -> #DIV/0! | W43: =ROUND(X43*100/15,2) -> 0 | X43: =IFERROR(TRUNC(SUM(T43+V43),2),"") | AB43: 32 | AC43: =B43 | AD43: =C43 | AT43: =AVERAGE(AE43:AS43) -> #DIV/0! | AU43: =IFERROR(TRUNC(AVERAGE(AE43:AT43),2),"")*10/100 -> 0 | AV43: =AT43 -> #DIV/0! | AW43: =AV43*5/100 -> #DIV/0! | AX43: =ROUND(AY43*100/15,2) -> 0 | AY43: =IFERROR(TRUNC(SUM(AU43+AW43),2),"") | BC43: 32 | BD43: =B43 | BE43: =C43 | BU43: =AVERAGE(BF43:BT43) -> #DIV/0! | BV43: =IFERROR(TRUNC(AVERAGE(BF43:BU43),2),"")*10/100 -> 0 | BW43: =BU43 -> #DIV/0! | BX43: =BW43*5/100 -> #DIV/0! | BY43: =ROUND(BZ43*100/15,2) -> 0 | BZ43: =IFERROR(TRUNC(SUM(BV43+BX43),2),"")
A44: 33 | S44: =AVERAGE(D44:Q44) -> #DIV/0! | T44: =IFERROR(TRUNC(AVERAGE(D44:S44),2),"")*10/100 -> 0 | U44: =S44 -> #DIV/0! | V44: =U44*5/100 -> #DIV/0! | W44: =ROUND(X44*100/15,2) -> 0 | X44: =IFERROR(TRUNC(SUM(T44+V44),2),"") | AB44: 33 | AC44: =B44 | AD44: =C44 | AT44: =AVERAGE(AE44:AS44) -> #DIV/0! | AU44: =IFERROR(TRUNC(AVERAGE(AE44:AT44),2),"")*10/100 -> 0 | AV44: =AT44 -> #DIV/0! | AW44: =AV44*5/100 -> #DIV/0! | AX44: =ROUND(AY44*100/15,2) -> 0 | AY44: =IFERROR(TRUNC(SUM(AU44+AW44),2),"") | BC44: 33 | BD44: =B44 | BE44: =C44 | BU44: =AVERAGE(BF44:BT44) -> #DIV/0! | BV44: =IFERROR(TRUNC(AVERAGE(BF44:BU44),2),"")*10/100 -> 0 | BW44: =BU44 -> #DIV/0! | BX44: =BW44*5/100 -> #DIV/0! | BY44: =ROUND(BZ44*100/15,2) -> 0 | BZ44: =IFERROR(TRUNC(SUM(BV44+BX44),2),"")
A45: 34 | S45: =AVERAGE(D45:Q45) -> #DIV/0! | T45: =IFERROR(TRUNC(AVERAGE(D45:S45),2),"")*10/100 -> 0 | U45: =S45 -> #DIV/0! | V45: =U45*5/100 -> #DIV/0! | W45: =ROUND(X45*100/15,2) -> 0 | X45: =IFERROR(TRUNC(SUM(T45+V45),2),"") | AB45: 34 | AC45: =B45 | AD45: =C45 | AT45: =AVERAGE(AE45:AS45) -> #DIV/0! | AU45: =IFERROR(TRUNC(AVERAGE(AE45:AT45),2),"")*10/100 -> 0 | AV45: =AT45 -> #DIV/0! | AW45: =AV45*5/100 -> #DIV/0! | AX45: =ROUND(AY45*100/15,2) -> 0 | AY45: =IFERROR(TRUNC(SUM(AU45+AW45),2),"") | BC45: 34 | BD45: =B45 | BE45: =C45 | BU45: =AVERAGE(BF45:BT45) -> #DIV/0! | BV45: =IFERROR(TRUNC(AVERAGE(BF45:BU45),2),"")*10/100 -> 0 | BW45: =BU45 -> #DIV/0! | BX45: =BW45*5/100 -> #DIV/0! | BY45: =ROUND(BZ45*100/15,2) -> 0 | BZ45: =IFERROR(TRUNC(SUM(BV45+BX45),2),"")
A46: 35 | S46: =AVERAGE(D46:Q46) -> #DIV/0! | T46: =IFERROR(TRUNC(AVERAGE(D46:S46),2),"")*10/100 -> 0 | U46: =S46 -> #DIV/0! | V46: =U46*5/100 -> #DIV/0! | W46: =ROUND(X46*100/15,2) -> 0 | X46: =IFERROR(TRUNC(SUM(T46+V46),2),"") | AB46: 35 | AC46: =B46 | AD46: =C46 | AT46: =AVERAGE(AE46:AS46) -> #DIV/0! | AU46: =IFERROR(TRUNC(AVERAGE(AE46:AT46),2),"")*10/100 -> 0 | AV46: =AT46 -> #DIV/0! | AW46: =AV46*5/100 -> #DIV/0! | AX46: =ROUND(AY46*100/15,2) -> 0 | AY46: =IFERROR(TRUNC(SUM(AU46+AW46),2),"") | BC46: 35 | BD46: =B46 | BE46: =C46 | BU46: =AVERAGE(BF46:BT46) -> #DIV/0! | BV46: =IFERROR(TRUNC(AVERAGE(BF46:BU46),2),"")*10/100 -> 0 | BW46: =BU46 -> #DIV/0! | BX46: =BW46*5/100 -> #DIV/0! | BY46: =ROUND(BZ46*100/15,2) -> 0 | BZ46: =IFERROR(TRUNC(SUM(BV46+BX46),2),"")
A47: 36 | S47: =AVERAGE(D47:Q47) -> #DIV/0! | T47: =IFERROR(TRUNC(AVERAGE(D47:S47),2),"")*10/100 -> 0 | U47: =S47 -> #DIV/0! | V47: =U47*5/100 -> #DIV/0! | W47: =ROUND(X47*100/15,2) -> 0 | X47: =IFERROR(TRUNC(SUM(T47+V47),2),"") | AB47: 36 | AC47: =B47 | AD47: =C47 | AT47: =AVERAGE(AE47:AS47) -> #DIV/0! | AU47: =IFERROR(TRUNC(AVERAGE(AE47:AT47),2),"")*10/100 -> 0 | AV47: =AT47 -> #DIV/0! | AW47: =AV47*5/100 -> #DIV/0! | AX47: =ROUND(AY47*100/15,2) -> 0 | AY47: =IFERROR(TRUNC(SUM(AU47+AW47),2),"") | BC47: 36 | BD47: =B47 | BE47: =C47 | BU47: =AVERAGE(BF47:BT47) -> #DIV/0! | BV47: =IFERROR(TRUNC(AVERAGE(BF47:BU47),2),"")*10/100 -> 0 | BW47: =BU47 -> #DIV/0! | BX47: =BW47*5/100 -> #DIV/0! | BY47: =ROUND(BZ47*100/15,2) -> 0 | BZ47: =IFERROR(TRUNC(SUM(BV47+BX47),2),"")
... A50: 39 | S50: =AVERAGE(D50:Q50) -> #DIV/0! | T50: =IFERROR(TRUNC(AVERAGE(D50:S50),2),"")*10/100 -> 0 | U50: =S50 -> #DIV/0! | V50: =U50*5/100 -> #DIV/0! | W50: =ROUND(X50*100/15,2) -> 0 | X50: =IFERROR(TRUNC(SUM(T50+V50),2),"") | AB50: 39 | AC50: =B50 | AD50: =C50 | AT50: =AVERAGE(AE50:AS50) -> #DIV/0! | AU50: =IFERROR(TRUNC(AVERAGE(AE50:AT50),2),"")*10/100 -> 0 | AV50: =AT50 -> #DIV/0! | AW50: =AV50*5/100 -> #DIV/0! | AX50: =ROUND(AY50*100/15,2) -> 0 | AY50: =IFERROR(TRUNC(SUM(AU50+AW50),2),"") | BC50: 39 | BD50: =B50 | BE50: =C50 | BU50: =AVERAGE(BF50:BT50) -> #DIV/0! | BV50: =IFERROR(TRUNC(AVERAGE(BF50:BU50),2),"")*10/100 -> 0 | BW50: =BU50 -> #DIV/0! | BX50: =BW50*5/100 -> #DIV/0! | BY50: =ROUND(BZ50*100/15,2) -> 0 | BZ50: =IFERROR(TRUNC(SUM(BV50+BX50),2),"")
A51: 40 | S51: =AVERAGE(D51:Q51) -> #DIV/0! | T51: =IFERROR(TRUNC(AVERAGE(D51:S51),2),"")*10/100 -> 0 | U51: =S51 -> #DIV/0! | V51: =U51*5/100 -> #DIV/0! | W51: =ROUND(X51*100/15,2) -> 0 | X51: =IFERROR(TRUNC(SUM(T51+V51),2),"") | AB51: 40 | AC51: =B51 | AD51: =C51 | AT51: =AVERAGE(AE51:AS51) -> #DIV/0! | AU51: =IFERROR(TRUNC(AVERAGE(AE51:AT51),2),"")*10/100 -> 0 | AV51: =AT51 -> #DIV/0! | AW51: =AV51*5/100 -> #DIV/0! | AX51: =ROUND(AY51*100/15,2) -> 0 | AY51: =IFERROR(TRUNC(SUM(AU51+AW51),2),"") | BC51: 40 | BU51: =AVERAGE(BF51:BT51) -> #DIV/0! | BV51: =IFERROR(TRUNC(AVERAGE(BF51:BU51),2),"")*10/100 -> 0 | BW51: =BU51 -> #DIV/0! | BX51: =BW51*5/100 -> #DIV/0! | BY51: =ROUND(BZ51*100/15,2) -> 0 | BZ51: =IFERROR(TRUNC(SUM(BV51+BX51),2),"")
A52: 41 | S52: =AVERAGE(D52:Q52) -> #DIV/0! | T52: =IFERROR(TRUNC(AVERAGE(D52:S52),2),"")*10/100 -> 0 | U52: =S52 -> #DIV/0! | V52: =U52*5/100 -> #DIV/0! | W52: =ROUND(X52*100/15,2) -> 0 | X52: =IFERROR(TRUNC(SUM(T52+V52),2),"") | AB52: 41 | AC52: =B52 | AD52: =C52 | AT52: =AVERAGE(AE52:AS52) -> #DIV/0! | AU52: =IFERROR(TRUNC(AVERAGE(AE52:AT52),2),"")*10/100 -> 0 | AV52: =AT52 -> #DIV/0! | AW52: =AV52*5/100 -> #DIV/0! | AX52: =ROUND(AY52*100/15,2) -> 0 | AY52: =IFERROR(TRUNC(SUM(AU52+AW52),2),"") | BC52: 41 | BU52: =AVERAGE(BF52:BT52) -> #DIV/0! | BV52: =IFERROR(TRUNC(AVERAGE(BF52:BU52),2),"")*10/100 -> 0 | BW52: =BU52 -> #DIV/0! | BX52: =BW52*5/100 -> #DIV/0! | BY52: =ROUND(BZ52*100/15,2) -> 0 | BZ52: =IFERROR(TRUNC(SUM(BV52+BX52),2),"")
A53: 42 | S53: =AVERAGE(D53:Q53) -> #DIV/0! | T53: =IFERROR(TRUNC(AVERAGE(D53:S53),2),"")*10/100 -> 0 | U53: =S53 -> #DIV/0! | V53: =U53*5/100 -> #DIV/0! | W53: =ROUND(X53*100/15,2) -> 0 | X53: =IFERROR(TRUNC(SUM(T53+V53),2),"") | AB53: 42 | AC53: =B53 | AD53: =C53 | AT53: =AVERAGE(AE53:AS53) -> #DIV/0! | AU53: =IFERROR(TRUNC(AVERAGE(AE53:AT53),2),"")*10/100 -> 0 | AV53: =AT53 -> #DIV/0! | AW53: =AV53*5/100 -> #DIV/0! | AX53: =ROUND(AY53*100/15,2) -> 0 | AY53: =IFERROR(TRUNC(SUM(AU53+AW53),2),"") | BC53: 42 | BU53: =AVERAGE(BF53:BT53) -> #DIV/0! | BV53: =IFERROR(TRUNC(AVERAGE(BF53:BU53),2),"")*10/100 -> 0 | BW53: =BU53 -> #DIV/0! | BX53: =BW53*5/100 -> #DIV/0! | BY53: =ROUND(BZ53*100/15,2) -> 0 | BZ53: =IFERROR(TRUNC(SUM(BV53+BX53),2),"")
A54: 43 | S54: =AVERAGE(D54:Q54) -> #DIV/0! | T54: =IFERROR(TRUNC(AVERAGE(D54:S54),2),"")*10/100 -> 0 | U54: =S54 -> #DIV/0! | V54: =U54*5/100 -> #DIV/0! | W54: =ROUND(X54*100/15,2) -> 0 | X54: =IFERROR(TRUNC(SUM(T54+V54),2),"") | AB54: 43 | AC54: =B54 | AD54: =C54 | AT54: =AVERAGE(AE54:AS54) -> #DIV/0! | AU54: =IFERROR(TRUNC(AVERAGE(AE54:AT54),2),"")*10/100 -> 0 | AV54: =AT54 -> #DIV/0! | AW54: =AV54*5/100 -> #DIV/0! | AX54: =ROUND(AY54*100/15,2) -> 0 | AY54: =IFERROR(TRUNC(SUM(AU54+AW54),2),"") | BC54: 43 | BU54: =AVERAGE(BF54:BT54) -> #DIV/0! | BV54: =IFERROR(TRUNC(AVERAGE(BF54:BU54),2),"")*10/100 -> 0 | BW54: =BU54 -> #DIV/0! | BX54: =BW54*5/100 -> #DIV/0! | BY54: =ROUND(BZ54*100/15,2) -> 0 | BZ54: =IFERROR(TRUNC(SUM(BV54+BX54),2),"")
A55: 44 | S55: =AVERAGE(D55:Q55) -> #DIV/0! | T55: =IFERROR(TRUNC(AVERAGE(D55:S55),2),"")*10/100 -> 0 | U55: =S55 -> #DIV/0! | V55: =U55*5/100 -> #DIV/0! | W55: =ROUND(X55*100/15,2) -> 0 | X55: =IFERROR(TRUNC(SUM(T55+V55),2),"") | AB55: 44 | AC55: =B55 | AD55: =C55 | AT55: =AVERAGE(AE55:AS55) -> #DIV/0! | AU55: =IFERROR(TRUNC(AVERAGE(AE55:AT55),2),"")*10/100 -> 0 | AV55: =AT55 -> #DIV/0! | AW55: =AV55*5/100 -> #DIV/0! | AX55: =ROUND(AY55*100/15,2) -> 0 | AY55: =IFERROR(TRUNC(SUM(AU55+AW55),2),"") | BC55: 44 | BU55: =AVERAGE(BF55:BT55) -> #DIV/0! | BV55: =IFERROR(TRUNC(AVERAGE(BF55:BU55),2),"")*10/100 -> 0 | BW55: =BU55 -> #DIV/0! | BX55: =BW55*5/100 -> #DIV/0! | BY55: =ROUND(BZ55*100/15,2) -> 0 | BZ55: =IFERROR(TRUNC(SUM(BV55+BX55),2),"")
...

Sheet LEN
A2: INSTITUCIÓN: | C2: UNIDAD EDUCATIVA EMILIO ISAÍAS ABIHANNA | AE2: INSTITUCIÓN: | AG2: =C2 -> UNIDAD EDUCATIVA EMILIO ISAÍAS ABIHANNA | BI2: INSTITUCIÓN: | BK2: =AG2 -> UNIDAD EDUCATIVA EMILIO ISAÍAS ABIHANNA | CM2: INSTITUCIÓN: | CO2: =BK2 -> UNIDAD EDUCATIVA EMILIO ISAÍAS ABIHANNA | CX2: INSTITUCIÓN: | CZ2: =CO2 -> UNIDAD EDUCATIVA EMILIO ISAÍAS ABIHANNA
A3: DOCENTE: | C3: LIC. XIMENA NAULA YUQUILEMA, MAG. | AE3: DOCENTE: | AG3: =C3 -> LIC. XIMENA NAULA YUQUILEMA, MAG. | BI3: DOCENTE: | BK3: =C3 -> LIC. XIMENA NAULA YUQUILEMA, MAG. | CM3: DOCENTE: | CO3: =C3 -> LIC. XIMENA NAULA YUQUILEMA, MAG. | CX3: DOCENTE: | CZ3: =C3 -> LIC. XIMENA NAULA YUQUILEMA, MAG.
A4: GRADO: | C4: 1ER. AÑO DE BACHILLERATO TECNICO | D4: PARALELO: | G4: B | AE4: GRADO: | AG4: =C4 -> 1ER. AÑO DE BACHILLERATO TECNICO | AH4: PARALELO: | AK4: =G4 -> B | BI4: GRADO: | BK4: =C4 -> 1ER. AÑO DE BACHILLERATO TECNICO | BL4: PARALELO: | BO4: =G4 -> B | CM4: GRADO: | CO4: =C4 -> 1ER. AÑO DE BACHILLERATO TECNICO | CP4: PARALELO: | CR4: =G4 -> B | CX4: GRADO: | CZ4: =C4 -> 1ER. AÑO DE BACHILLERATO TECNICO | DA4: PARALELO: | DD4: =G4 -> B
A6: PRIMER TRIMESTRE | AE6: SEGUNDO TRIMESTRE | BI6: TERCER TRIMESTRE | CM6: CALIFICACIONES TRIMESTRALES | CX6: SUPLETORIO
A7: MATERIA: LENGUAJE | AE7: =A7 -> MATERIA: LENGUAJE | BI7: =A7 -> MATERIA: LENGUAJE | CM7: =A7 -> MATERIA: LENGUAJE | CX7: =A7 -> MATERIA: LENGUAJE
A8: ESTUDIANTES | D8: EVALUACIÓN FORMATIVA | T8: REFUERZO PEDAGÓGICO | V8: TOTAL 70% | W8: EXAMEN DEL PRIMER TRIMESTRE | X8: PROYECTO INTERDISCIPLINARIO | Y8: EVALUACIÓN SUMATIVA (PROMEDIO DE EXAMEN+PROYECTO INTERDISCIPLINARIO) | Z8: 0.3 | AA8: TOTAL TRIMESTRE (100%) | AE8: ESTUDIANTES | AH8: EVALUACIÓN FORMATIVA | AX8: REFUERZO PEDAGÓGICO | AZ8: TOTAL 70% | BA8: EXAMEN DEL PRIMER TRIMESTRE | BB8: PROYECTO INTERDISCIPLINARIO | BC8: EVALUACIÓN SUMATIVA (PROMEDIO DE EXAMEN+PROYECTO INTERDISCIPLINARIO) | BD8: 0.3 | BE8: TOTAL TRIMESTRE (100%) | BI8: ESTUDIANTES | BL8: EVALUACIÓN FORMATIVA | CB8: REFUERZO PEDAGÓGICO | CD8: TOTAL 70% | CE8: EXAMEN DEL PRIMER TRIMESTRE | CF8: PROYECTO INTERDISCIPLINARIO | CG8: EVALUACIÓN SUMATIVA (PROMEDIO DE EXAMEN+PROYECTO INTERDISCIPLINARIO) | CH8: 0.3 | CI8: TOTAL TRIMESTRE (100%)
D9: APORTES DISCIPLINARES O INTERDISCIPLINARES INDIVIDUALES | L9: APORTES DISCIPLINARES O INTERDISCIPLINARES GRUPALES | AH9: APORTES DISCIPLINARES O INTERDISCIPLINARES INDIVIDUALES | AP9: APORTES DISCIPLINARES O INTERDISCIPLINARES GRUPALES | BL9: APORTES DISCIPLINARES O INTERDISCIPLINARES INDIVIDUALES | BT9: APORTES DISCIPLINARES O INTERDISCIPLINARES GRUPALES | CP9: =LEN!CM10 -> ESTUDIANTES
D10: Lecciones | F10: Pruebas | H10: Tareas | J10: Proyectos | L10: Proyectos | N10: Exposiciones | P10: Talleres | R10: Productos | AH10: Lecciones | AJ10: Pruebas | AL10: Tareas | AN10: Proyectos | AP10: Proyectos | AR10: Exposiciones | AT10: Talleres | AV10: Productos | BL10: Lecciones | BN10: Pruebas | BP10: Tareas | BR10: Proyectos | BT10: Proyectos | BV10: Exposiciones | BX10: Talleres | BZ10: Productos | CM10: ESTUDIANTES | CP10: TRIMESTRES | CS10: NOTA FINAL (100%) | CT10: OBSERVACIÓN | CZ10: ESTUDIANTES | DA10: CUANTIFICACION DE NOTA FINAL /ANUAL
A11: Nº | B11: CÉDULA | C11: APELLIDOS/NOMBRES | D11: INSUMO 1 | E11: INSUMO 2 | F11: INSUMO 1 | G11: INSUMO 2 | H11: INSUMO 1 | I11: INSUMO 2 | J11: INSUMO 1 | K11: INSUMO 2 | L11: INSUMO 1 | M11: INSUMO 2 | N11: INSUMO 1 | O11: INSUMO 2 | P11: INSUMO 1 | Q11: INSUMO 2 | R11: INSUMO 1 | S11: INSUMO 2 | AE11: Nº | AF11: CÉDULA | AG11: APELLIDOS/NOMBRES | AH11: INSUMO 1 | AI11: INSUMO 2 | AJ11: INSUMO 1 | AK11: INSUMO 2 | AL11: INSUMO 1 | AM11: INSUMO 2 | AN11: INSUMO 1 | AO11: INSUMO 2 | AP11: INSUMO 1 | AQ11: INSUMO 2 | AR11: INSUMO 1 | AS11: INSUMO 2 | AT11: INSUMO 1 | AU11: INSUMO 2 | AV11: INSUMO 1 | AW11: INSUMO 2 | BI11: Nº | BJ11: CÉDULA | BK11: APELLIDOS/NOMBRES | BL11: INSUMO 1 | BM11: INSUMO 2 | BN11: INSUMO 1 | BO11: INSUMO 2 | BP11: INSUMO 1 | BQ11: INSUMO 2 | BR11: INSUMO 1 | BS11: INSUMO 2 | BT11: INSUMO 1 | BU11: INSUMO 2 | BV11: INSUMO 1 | BW11: INSUMO 2 | BX11: INSUMO 1 | BY11: INSUMO 2 | BZ11: INSUMO 1 | CA11: INSUMO 2 | CM11: Nº | CN11: CÉDULA | CO11: APELLIDOS/NOMBRES | CP11: 1er | CQ11: 2do | CR11: 3er | CX11: Nº | CY11: CÉDULA | CZ11: APELLIDOS/NOMBRES | DA11: CALF. FINAL | DB11: EXA. SUPLET | DC11: FINAL ANUAL | DD11: OBSERVACIÓN
A12: 1 | B12: ='PROY. INTER'!B12 | C12: ='PROY. INTER'!C12 -> Almeida Alvarado Ariana Guisela | D12: 10 | H12: 10 | N12: 7 | P12: 9 | V12: =IFERROR(TRUNC(AVERAGE(D12:U12),2),"")*70/100 -> 6.3 | W12: 10 | X12: ='PROY. INTER'!W12 -> 10 | Y12: =AVERAGE(W12:X12) -> 10 | Z12: =Y12*30/100 -> 3 | AA12: =IFERROR(TRUNC(SUM(V12+Z12),2),"") -> 9.3 | AE12: 1 | AF12: =B12 | AG12: =C12 -> Almeida Alvarado Ariana Guisela | AH12: 10 | AL12: 9.5 | AR12: 10 | AT12: 10 | AZ12: =IFERROR(TRUNC(AVERAGE(AH12:AY12),2),"")*70/100 -> 6.909 | BA12: 9 | BB12: ='PROY. INTER'!AX12 -> 10 | BC12: =AVERAGE(BA12:BB12) -> 9.5 | BD12: =BC12*30/100 -> 2.85 | BE12: =IFERROR(TRUNC(SUM(AZ12+BD12),2),"") -> 9.75 | BI12: 1 | BJ12: =B12 | BK12: =C12 -> Almeida Alvarado Ariana Guisela | CD12: =IFERROR(TRUNC(AVERAGE(BL12:CC12),2),"")*70/100 -> 0 | CF12: ='PROY. INTER'!BY12 -> 0 | CG12: =AVERAGE(CE12:CF12) -> 0 | CH12: =CG12*30/100 -> 0 | CI12: =IFERROR(TRUNC(SUM(CD12+CH12),2),"") -> 0 | CM12: 1 | CN12: =B12 | CO12: =C12 -> Almeida Alvarado Ariana Guisela | CP12: =AA12 -> 9.3 | CQ12: =BE12 -> 9.75 | CR12: =CI12 -> 0 | CS12: =IFERROR(TRUNC(AVERAGE(CP12:CR12),2),"")*100/100 -> 6.35 | CT12: =IF(CS12="","",IF(CS12>=7,"APROBADO",IF(AND(CS12<=6.99,CS12>=5),"SUPLETORIO","REPROBADO"))) -> SUPLETORIO | CX12: 1 | CY12: =B12 | CZ12: =C12 -> Almeida Alvarado Ariana Guisela | DA12: =CS12 -> 6.35 | DC12: =IF(DA12>=7,DA12,IF(DA12="","",IF(DB12="",AVERAGE(DA12:DB12),IF(AND(DA12<4.01,DB12<>""),DA12,IF(DB12<7,DA12,7))))) -> 6.35 | DD12: =IF(AND(DA12>=7,DB12<>""),"DEJE EN BLANCO EL CASILLERO SUPLETORIO",IF(DA12="","",IF(AND(DA12<5,DB12<>""),"NO PUEDE RENDIR SUPLETORIO;REPRUEBA EL GRADO",IF(DC12<7,"NO PROMOVIDO","PROMOVIDO")))) -> NO PROMOVIDO
A13: 2 | B13: ='PROY. INTER'!B13 | C13: ='PROY. INTER'!C13 -> Alvarado Vargas Dacmar Alejandra | D13: 10 | H13: 10 | N13: 7 | P13: 9 | V13: =IFERROR(TRUNC(AVERAGE(D13:U13),2),"")*70/100 -> 6.3 | W13: 10 | X13: ='PROY. INTER'!W13 -> 10 | Y13: =AVERAGE(W13:X13) -> 10 | Z13: =Y13*30/100 -> 3 | AA13: =IFERROR(TRUNC(SUM(V13+Z13),2),"") -> 9.3 | AE13: 2 | AF13: =B13 | AG13: =C13 -> Alvarado Vargas Dacmar Alejandra | AH13: 9.5 | AL13: 9.5 | AR13: 9 | AT13: 10 | AZ13: =IFERROR(TRUNC(AVERAGE(AH13:AY13),2),"")*70/100 -> 6.65 | BA13: 8 | BB13: ='PROY. INTER'!AX13 -> 10 | BC13: =AVERAGE(BA13:BB13) -> 9 | BD13: =BC13*30/100 -> 2.7 | BE13: =IFERROR(TRUNC(SUM(AZ13+BD13),2),"") -> 9.35 | BI13: 2 | BJ13: =B13 | BK13: =C13 -> Alvarado Vargas Dacmar Alejandra | CD13: =IFERROR(TRUNC(AVERAGE(BL13:CC13),2),"")*70/100 -> 0 | CF13: ='PROY. INTER'!BY13 -> 0 | CG13: =AVERAGE(CE13:CF13) -> 0 | CH13: =CG13*30/100 -> 0 | CI13: =IFERROR(TRUNC(SUM(CD13+CH13),2),"") -> 0 | CM13: 2 | CN13: =B13 | CO13: =C13 -> Alvarado Vargas Dacmar Alejandra | CP13: =AA13 -> 9.3 | CQ13: =BE13 -> 9.35 | CR13: =CI13 -> 0 | CS13: =IFERROR(TRUNC(AVERAGE(CP13:CR13),2),"")*100/100 -> 6.21 | CT13: =IF(CS13="","",IF(CS13>=7,"APROBADO",IF(AND(CS13<=6.99,CS13>=5),"SUPLETORIO","REPROBADO"))) -> SUPLETORIO | CX13: 2 | CY13: =B13 | CZ13: =C13 -> Alvarado Vargas Dacmar Alejandra | DA13: =CS13 -> 6.21 | DC13: =IF(DA13>=7,DA13,IF(DA13="","",IF(DB13="",AVERAGE(DA13:DB13),IF(AND(DA13<4.01,DB13<>""),DA13,IF(DB13<7,DA13,7))))) -> 6.21 | DD13: =IF(AND(DA13>=7,DB13<>""),"DEJE EN BLANCO EL CASILLERO SUPLETORIO",IF(DA13="","",IF(AND(DA13<5,DB13<>""),"NO PUEDE RENDIR SUPLETORIO;REPRUEBA EL GRADO",IF(DC13<7,"NO PROMOVIDO","PROMOVIDO")))) -> NO PROMOVIDO
A14: 3 | B14: ='PROY. INTER'!B14 | C14: ='PROY. INTER'!C14 -> Ampuero Cornejo Cesar Jeanpierre | D14: 7 | H14: 8 | N14: 8 | P14: 9 | V14: =IFERROR(TRUNC(AVERAGE(D14:U14),2),"")*70/100 -> 5.6 | W14: 10 | X14: ='PROY. INTER'!W14 -> 8.2 | Y14: =AVERAGE(W14:X14) -> 9.1 | Z14: =Y14*30/100 -> 2.73 | AA14: =IFERROR(TRUNC(SUM(V14+Z14),2),"") -> 8.33 | AE14: 3 | AF14: =B14 | AG14: =C14 -> Ampuero Cornejo Cesar Jeanpierre | AH14: 8 | AL14: 9 | AR14: 8 | AT14: 7 | AZ14: =IFERROR(TRUNC(AVERAGE(AH14:AY14),2),"")*70/100 -> 5.6 | BA14: 7 | BB14: ='PROY. INTER'!AX14 -> 10 | BC14: =AVERAGE(BA14:BB14) -> 8.5 | BD14: =BC14*30/100 -> 2.55 | BE14: =IFERROR(TRUNC(SUM(AZ14+BD14),2),"") -> 8.15 | BI14: 3 | BJ14: =B14 | BK14: =C14 -> Ampuero Cornejo Cesar Jeanpierre | CD14: =IFERROR(TRUNC(AVERAGE(BL14:CC14),2),"")*70/100 -> 0 | CF14: ='PROY. INTER'!BY14 -> 0 | CG14: =AVERAGE(CE14:CF14) -> 0 | CH14: =CG14*30/100 -> 0 | CI14: =IFERROR(TRUNC(SUM(CD14+CH14),2),"") -> 0 | CM14: 3 | CN14: =B14 | CO14: =C14 -> Ampuero Cornejo Cesar Jeanpierre | CP14: =AA14 -> 8.33 | CQ14: =BE14 -> 8.15 | CR14: =CI14 -> 0 | CS14: =IFERROR(TRUNC(AVERAGE(CP14:CR14),2),"")*100/100 -> 5.49 | CT14: =IF(CS14="","",IF(CS14>=7,"APROBADO",IF(AND(CS14<=6.99,CS14>=5),"SUPLETORIO","REPROBADO"))) -> SUPLETORIO | CX14: 3 | CY14: =B14 | CZ14: =C14 -> Ampuero Cornejo Cesar Jeanpierre | DA14: =CS14 -> 5.49 | DC14: =IF(DA14>=7,DA14,IF(DA14="","",IF(DB14="",AVERAGE(DA14:DB14),IF(AND(DA14<4.01,DB14<>""),DA14,IF(DB14<7,DA14,7))))) -> 5.49 | DD14: =IF(AND(DA14>=7,DB14<>""),"DEJE EN BLANCO EL CASILLERO SUPLETORIO",IF(DA14="","",IF(AND(DA14<5,DB14<>""),"NO PUEDE RENDIR SUPLETORIO;REPRUEBA EL GRADO",IF(DC14<7,"NO PROMOVIDO","PROMOVIDO")))) -> NO PROMOVIDO
A15: 4 | B15: ='PROY. INTER'!B15 | C15: ='PROY. INTER'!C15 -> Aylla Murillo Kerly Kristhel | D15: 7 | H15: 7 | N15: 7 | P15: 7 | V15: =IFERROR(TRUNC(AVERAGE(D15:U15),2),"")*70/100 -> 4.9 | W15: 10 | X15: ='PROY. INTER'!W15 -> 6.73 | Y15: =AVERAGE(W15:X15) -> 8.365 | Z15: =Y15*30/100 -> 2.5095 | AA15: =IFERROR(TRUNC(SUM(V15+Z15),2),"") -> 7.4 | AE15: 4 | AF15: =B15 | AG15: =C15 -> Aylla Murillo Kerly Kristhel | AH15: 9 | AL15: 9.5 | AR15: 8 | AT15: 10 | AZ15: =IFERROR(TRUNC(AVERAGE(AH15:AY15),2),"")*70/100 -> 6.384 | BA15: 7 | BB15: ='PROY. INTER'!AX15 -> 10 | BC15: =AVERAGE(BA15:BB15) -> 8.5 | BD15: =BC15*30/100 -> 2.55 | BE15: =IFERROR(TRUNC(SUM(AZ15+BD15),2),"") -> 8.93 | BI15: 4 | BJ15: =B15 | BK15: =C15 -> Aylla Murillo Kerly Kristhel | CD15: =IFERROR(TRUNC(AVERAGE(BL15:CC15),2),"")*70/100 -> 0 | CF15: ='PROY. INTER'!BY15 -> 0 | CG15: =AVERAGE(CE15:CF15) -> 0 | CH15: =CG15*30/100 -> 0 | CI15: =IFERROR(TRUNC(SUM(CD15+CH15),2),"") -> 0 | CM15: 4 | CN15: =B15 | CO15: =C15 -> Aylla Murillo Kerly Kristhel | CP15: =AA15 -> 7.4 | CQ15: =BE15 -> 8.93 | CR15: =CI15 -> 0 | CS15: =IFERROR(TRUNC(AVERAGE(CP15:CR15),2),"")*100/100 -> 5.44 | CT15: =IF(CS15="","",IF(CS15>=7,"APROBADO",IF(AND(CS15<=6.99,CS15>=5),"SUPLETORIO","REPROBADO"))) -> SUPLETORIO | CX15: 4 | CY15: =B15 | CZ15: =C15 -> Aylla Murillo Kerly Kristhel | DA15: =CS15 -> 5.44 | DC15: =IF(DA15>=7,DA15,IF(DA15="","",IF(DB15="",AVERAGE(DA15:DB15),IF(AND(DA15<4.01,DB15<>""),DA15,IF(DB15<7,DA15,7))))) -> 5.44 | DD15: =IF(AND(DA15>=7,DB15<>""),"DEJE EN BLANCO EL CASILLERO SUPLETORIO",IF(DA15="","",IF(AND(DA15<5,DB15<>""),"NO PUEDE RENDIR SUPLETORIO;REPRUEBA EL GRADO",IF(DC15<7,"NO PROMOVIDO","PROMOVIDO")))) -> NO PROMOVIDO
A16: 5 | B16: ='PROY. INTER'!B16 | C16: ='PROY. INTER'!C16 -> Campuzano Meza Naydelyn Odeth | D16: 7 | H16: 7 | N16: 8 | P16: 9 | V16: =IFERROR(TRUNC(AVERAGE(D16:U16),2),"")*70/100 -> 5.425 | W16: 10 | X16: ='PROY. INTER'!W16 -> 6 | Y16: =AVERAGE(W16:X16) -> 8 | Z16: =Y16*30/100 -> 2.4 | AA16: =IFERROR(TRUNC(SUM(V16+Z16),2),"") -> 7.82 | AE16: 5 | AF16: =B16 | AG16: =C16 -> Campuzano Meza Naydelyn Odeth | AH16: 7 | AL16: 7 | AR16: 8.35 | AT16: 10 | AZ16: =IFERROR(TRUNC(AVERAGE(AH16:AY16),2),"")*70/100 -> 5.656 | BA16: 7 | BB16: ='PROY. INTER'!AX16 -> 2 | BC16: =AVERAGE(BA16:BB16) -> 4.5 | BD16: =BC16*30/100 -> 1.35 | BE16: =IFERROR(TRUNC(SUM(AZ16+BD16),2),"") -> 7 | BI16: 5 | BJ16: =B16 | BK16: =C16 -> Campuzano Meza Naydelyn Odeth | CD16: =IFERROR(TRUNC(AVERAGE(BL16:CC16),2),"")*70/100 -> 0 | CF16: ='PROY. INTER'!BY16 -> 0 | CG16: =AVERAGE(CE16:CF16) -> 0 | CH16: =CG16*30/100 -> 0 | CI16: =IFERROR(TRUNC(SUM(CD16+CH16),2),"") -> 0 | CM16: 5 | CN16: =B16 | CO16: =C16 -> Campuzano Meza Naydelyn Odeth | CP16: =AA16 -> 7.82 | CQ16: =BE16 -> 7 | CR16: =CI16 -> 0 | CS16: =IFERROR(TRUNC(AVERAGE(CP16:CR16),2),"")*100/100 -> 4.94 | CT16: =IF(CS16="","",IF(CS16>=7,"APROBADO",IF(AND(CS16<=6.99,CS16>=5),"SUPLETORIO","REPROBADO"))) -> REPROBADO | CX16: 5 | CY16: =B16 | CZ16: =C16 -> Campuzano Meza Naydelyn Odeth | DA16: =CS16 -> 4.94 | DC16: =IF(DA16>=7,DA16,IF(DA16="","",IF(DB16="",AVERAGE(DA16:DB16),IF(AND(DA16<4.01,DB16<>""),DA16,IF(DB16<7,DA16,7))))) -> 4.94 | DD16: =IF(AND(DA16>=7,DB16<>""),"DEJE EN BLANCO EL CASILLERO SUPLETORIO",IF(DA16="","",IF(AND(DA16<5,DB16<>""),"NO PUEDE RENDIR SUPLETORIO;REPRUEBA EL GRADO",IF(DC16<7,"NO PROMOVIDO","PROMOVIDO")))) -> NO PROMOVIDO
A17: 6 | B17: ='PROY. INTER'!B17 | C17: ='PROY. INTER'!C17 -> Cantos Zúñiga a Hernán Snayder | D17: 7 | H17: 8 | N17: 7 | P17: 9 | V17: =IFERROR(TRUNC(AVERAGE(D17:U17),2),"")*70/100 -> 5.425 | W17: 10 | X17: ='PROY. INTER'!W17 -> 9.87 | Y17: =AVERAGE(W17:X17) -> 9.935 | Z17: =Y17*30/100 -> 2.9805 | AA17: =IFERROR(TRUNC(SUM(V17+Z17),2),"") -> 8.4 | AE17: 6 | AF17: =B17 | AG17: =C17 -> Cantos Zúñiga a Hernán Snayder | AH17: 7 | AL17: 7 | AR17: 9 | AT17: 10 | AZ17: =IFERROR(TRUNC(AVERAGE(AH17:AY17),2),"")*70/100 -> 5.775 | BA17: 9 | BB17: ='PROY. INTER'!AX17 -> 10 | BC17: =AVERAGE(BA17:BB17) -> 9.5 | BD17: =BC17*30/100 -> 2.85 | BE17: =IFERROR(TRUNC(SUM(AZ17+BD17),2),"") -> 8.62 | BI17: 6 | BJ17: =B17 | BK17: =C17 -> Cantos Zúñiga a Hernán Snayder | CD17: =IFERROR(TRUNC(AVERAGE(BL17:CC17),2),"")*70/100 -> 0 | CF17: ='PROY. INTER'!BY17 -> 0 | CG17: =AVERAGE(CE17:CF17) -> 0 | CH17: =CG17*30/100 -> 0 | CI17: =IFERROR(TRUNC(SUM(CD17+CH17),2),"") -> 0 | CM17: 6 | CN17: =B17 | CO17: =C17 -> Cantos Zúñiga a Hernán Snayder | CP17: =AA17 -> 8.4 | CQ17: =BE17 -> 8.62 | CR17: =CI17 -> 0 | CS17: =IFERROR(TRUNC(AVERAGE(CP17:CR17),2),"")*100/100 -> 5.67 | CT17: =IF(CS17="","",IF(CS17>=7,"APROBADO",IF(AND(CS17<=6.99,CS17>=5),"SUPLETORIO","REPROBADO"))) -> SUPLETORIO | CX17: 6 | CY17: =B17 | CZ17: =C17 -> Cantos Zúñiga a Hernán Snayder | DA17: =CS17 -> 5.67 | DC17: =IF(DA17>=7,DA17,IF(DA17="","",IF(DB17="",AVERAGE(DA17:DB17),IF(AND(DA17<4.01,DB17<>""),DA17,IF(DB17<7,DA17,7))))) -> 5.67 | DD17: =IF(AND(DA17>=7,DB17<>""),"DEJE EN BLANCO EL CASILLERO SUPLETORIO",IF(DA17="","",IF(AND(DA17<5,DB17<>""),"NO PUEDE RENDIR SUPLETORIO;REPRUEBA EL GRADO",IF(DC17<7,"NO PROMOVIDO","PROMOVIDO")))) -> NO PROMOVIDO
A18: 7 | B18: ='PROY. INTER'!B18 | C18: ='PROY. INTER'!C18 -> Carranza Dumes Genesis Daniela | D18: 10 | H18: 10 | N18: 7 | P18: 9 | V18: =IFERROR(TRUNC(AVERAGE(D18:U18),2),"")*70/100 -> 6.3 | W18: 10 | X18: ='PROY. INTER'!W18 -> 9 | Y18: =AVERAGE(W18:X18) -> 9.5 | Z18: =Y18*30/100 -> 2.85 | AA18: =IFERROR(TRUNC(SUM(V18+Z18),2),"") -> 9.15 | AE18: 7 | AF18: =B18 | AG18: =C18 -> Carranza Dumes Genesis Daniela | AH18: 9 | AL18: 8 | AR18: 8 | AT18: 8 | AZ18: =IFERROR(TRUNC(AVERAGE(AH18:AY18),2),"")*70/100 -> 5.775 | BA18: 8 | BB18: ='PROY. INTER'!AX18 -> 2 | BC18: =AVERAGE(BA18:BB18) -> 5 | BD18: =BC18*30/100 -> 1.5 | BE18: =IFERROR(TRUNC(SUM(AZ18+BD18),2),"") -> 7.27 | BI18: 7 | BJ18: =B18 | BK18: =C18 -> Carranza Dumes Genesis Daniela | CD18: =IFERROR(TRUNC(AVERAGE(BL18:CC18),2),"")*70/100 -> 0 | CF18: ='PROY. INTER'!BY18 -> 0 | CG18: =AVERAGE(CE18:CF18) -> 0 | CH18: =CG18*30/100 -> 0 | CI18: =IFERROR(TRUNC(SUM(CD18+CH18),2),"") -> 0 | CM18: 7 | CN18: =B18 | CO18: =C18 -> Carranza Dumes Genesis Daniela | CP18: =AA18 -> 9.15 | CQ18: =BE18 -> 7.27 | CR18: =CI18 -> 0 | CS18: =IFERROR(TRUNC(AVERAGE(CP18:CR18),2),"")*100/100 -> 5.47 | CT18: =IF(CS18="","",IF(CS18>=7,"APROBADO",IF(AND(CS18<=6.99,CS18>=5),"SUPLETORIO","REPROBADO"))) -> SUPLETORIO | CX18: 7 | CY18: =B18 | CZ18: =C18 -> Carranza Dumes Genesis Daniela | DA18: =CS18 -> 5.47 | DC18: =IF(DA18>=7,DA18,IF(DA18="","",IF(DB18="",AVERAGE(DA18:DB18),IF(AND(DA18<4.01,DB18<>""),DA18,IF(DB18<7,DA18,7))))) -> 5.47 | DD18: =IF(AND(DA18>=7,DB18<>""),"DEJE EN BLANCO EL CASILLERO SUPLETORIO",IF(DA18="","",IF(AND(DA18<5,DB18<>""),"NO PUEDE RENDIR SUPLETORIO;REPRUEBA EL GRADO",IF(DC18<7,"NO PROMOVIDO","PROMOVIDO")))) -> NO PROMOVIDO
A19: 8 | B19: ='PROY. INTER'!B19 | C19: ='PROY. INTER'!C19 -> Castro De La Rosa Cristopher Ruben | D19: 7 | H19: 2.35 | N19: 8 | P19: 9 | V19: =IFERROR(TRUNC(AVERAGE(D19:U19),2),"")*70/100 -> 4.606 | W19: 10 | X19: ='PROY. INTER'!W19 -> 6 | Y19: =AVERAGE(W19:X19) -> 8 | Z19: =Y19*30/100 -> 2.4 | AA19: =IFERROR(TRUNC(SUM(V19+Z19),2),"") -> 7 | AE19: 8 | AF19: =B19 | AG19: =C19 -> Castro De La Rosa Cristopher Ruben | AH19: 7.9 | AL19: 7.9 | AR19: 8.5 | AT19: 8.05 | AZ19: =IFERROR(TRUNC(AVERAGE(AH19:AY19),2),"")*70/100 -> 5.656 | BA19: 7 | BB19: ='PROY. INTER'!AX19 -> 2 | BC19: =AVERAGE(BA19:BB19) -> 4.5 | BD19: =BC19*30/100 -> 1.35 | BE19: =IFERROR(TRUNC(SUM(AZ19+BD19),2),"") -> 7 | BI19: 8 | BJ19: =B19 | BK19: =C19 -> Castro De La Rosa Cristopher Ruben | CD19: =IFERROR(TRUNC(AVERAGE(BL19:CC19),2),"")*70/100 -> 0 | CF19: ='PROY. INTER'!BY19 -> 0 | CG19: =AVERAGE(CE19:CF19) -> 0 | CH19: =CG19*30/100 -> 0 | CI19: =IFERROR(TRUNC(SUM(CD19+CH19),2),"") -> 0 | CM19: 8 | CN19: =B19 | CO19: =C19 -> Castro De La Rosa Cristopher Ruben | CP19: =AA19 -> 7 | CQ19: =BE19 -> 7 | CR19: =CI19 -> 0 | CS19: =IFERROR(TRUNC(AVERAGE(CP19:CR19),2),"")*100/100 -> 4.66 | CT19: =IF(CS19="","",IF(CS19>=7,"APROBADO",IF(AND(CS19<=6.99,CS19>=5),"SUPLETORIO","REPROBADO"))) -> REPROBADO | CX19: 8 | CY19: =B19 | CZ19: =C19 -> Castro De La Rosa Cristopher Ruben | DA19: =CS19 -> 4.66 | DC19: =IF(DA19>=7,DA19,IF(DA19="","",IF(DB19="",AVERAGE(DA19:DB19),IF(AND(DA19<4.01,DB19<>""),DA19,IF(DB19<7,DA19,7))))) -> 4.66 | DD19: =IF(AND(DA19>=7,DB19<>""),"DEJE EN BLANCO EL CASILLERO SUPLETORIO",IF(DA19="","",IF(AND(DA19<5,DB19<>""),"NO PUEDE RENDIR SUPLETORIO;REPRUEBA EL GRADO",IF(DC19<7,"NO PROMOVIDO","PROMOVIDO")))) -> NO PROMOVIDO
A20: 9 | B20: ='PROY. INTER'!B20 | C20: ='PROY. INTER'!C20 -> Chamba Maurad Joshelyn Juleixi | D20: 7 | H20: 7 | N20: 8 | P20: 7 | V20: =IFERROR(TRUNC(AVERAGE(D20:U20),2),"")*70/100 -> 5.075 | W20: 7 | X20: ='PROY. INTER'!W20 -> 6 | Y20: =AVERAGE(W20:X20) -> 6.5 | Z20: =Y20*30/100 -> 1.95 | AA20: =IFERROR(TRUNC(SUM(V20+Z20),2),"") -> 7.02 | AE20: 9 | AF20: =B20 | AG20: =C20 -> Chamba Maurad Joshelyn Juleixi | AH20: 7 | AL20: 8 | AR20: 8 | AT20: 5 | AZ20: =IFERROR(TRUNC(AVERAGE(AH20:AY20),2),"")*70/100 -> 4.9 | BA20: 7 | BB20: ='PROY. INTER'!AX20 -> 10 | BC20: =AVERAGE(BA20:BB20) -> 8.5 | BD20: =BC20*30/100 -> 2.55 | BE20: =IFERROR(TRUNC(SUM(AZ20+BD20),2),"") -> 7.45 | BI20: 9 | BJ20: =B20 | BK20: =C20 -> Chamba Maurad Joshelyn Juleixi | CD20: =IFERROR(TRUNC(AVERAGE(BL20:CC20),2),"")*70/100 -> 0 | CF20: ='PROY. INTER'!BY20 -> 0 | CG20: =AVERAGE(CE20:CF20) -> 0 | CH20: =CG20*30/100 -> 0 | CI20: =IFERROR(TRUNC(SUM(CD20+CH20),2),"") -> 0 | CM20: 9 | CN20: =B20 | CO20: =C20 -> Chamba Maurad Joshelyn Juleixi | CP20: =AA20 -> 7.02 | CQ20: =BE20 -> 7.45 | CR20: =CI20 -> 0 | CS20: =IFERROR(TRUNC(AVERAGE(CP20:CR20),2),"")*100/100 -> 4.82 | CT20: =IF(CS20="","",IF(CS20>=7,"APROBADO",IF(AND(CS20<=6.99,CS20>=5),"SUPLETORIO","REPROBADO"))) -> REPROBADO | CX20: 9 | CY20: =B20 | CZ20: =C20 -> Chamba Maurad Joshelyn Juleixi | DA20: =CS20 -> 4.82 | DC20: =IF(DA20>=7,DA20,IF(DA20="","",IF(DB20="",AVERAGE(DA20:DB20),IF(AND(DA20<4.01,DB20<>""),DA20,IF(DB20<7,DA20,7))))) -> 4.82 | DD20: =IF(AND(DA20>=7,DB20<>""),"DEJE EN BLANCO EL CASILLERO SUPLETORIO",IF(DA20="","",IF(AND(DA20<5,DB20<>""),"NO PUEDE RENDIR SUPLETORIO;REPRUEBA EL GRADO",IF(DC20<7,"NO PROMOVIDO","PROMOVIDO")))) -> NO PROMOVIDO
A21: 10 | B21: ='PROY. INTER'!B21 | C21: ='PROY. INTER'!C21 -> Cedeño Sanchez Josué | D21: 7 | H21: 7 | N21: 8 | P21: 7 | V21: =IFERROR(TRUNC(AVERAGE(D21:U21),2),"")*70/100 -> 5.075 | W21: 7 | X21: ='PROY. INTER'!W21 -> 6 | Y21: =AVERAGE(W21:X21) -> 6.5 | Z21: =Y21*30/100 -> 1.95 | AA21: =IFERROR(TRUNC(SUM(V21+Z21),2),"") -> 7.02 | AE21: 10 | AF21: =B21 | AG21: =C21 -> Cedeño Sanchez Josué | AH21: 7.3 | AL21: 7.9 | AR21: 8 | AT21: 8 | AZ21: =IFERROR(TRUNC(AVERAGE(AH21:AY21),2),"")*70/100 -> 5.46 | BA21: 8.3 | BB21: ='PROY. INTER'!AX21 -> 2 | BC21: =AVERAGE(BA21:BB21) -> 5.15 | BD21: =BC21*30/100 -> 1.545 | BE21: =IFERROR(TRUNC(SUM(AZ21+BD21),2),"") -> 7 | BI21: 10 | BJ21: =B21 | BK21: =C21 -> Cedeño Sanchez Josué | CD21: =IFERROR(TRUNC(AVERAGE(BL21:CC21),2),"")*70/100 -> 0 | CF21: ='PROY. INTER'!BY21 -> 0 | CG21: =AVERAGE(CE21:CF21) -> 0 | CH21: =CG21*30/100 -> 0 | CI21: =IFERROR(TRUNC(SUM(CD21+CH21),2),"") -> 0 | CM21: 10 | CN21: =B21 | CO21: =C21 -> Cedeño Sanchez Josué | CP21: =AA21 -> 7.02 | CQ21: =BE21 -> 7 | CR21: =CI21 -> 0 | CS21: =IFERROR(TRUNC(AVERAGE(CP21:CR21),2),"")*100/100 -> 4.67 | CT21: =IF(CS21="","",IF(CS21>=7,"APROBADO",IF(AND(CS21<=6.99,CS21>=5),"SUPLETORIO","REPROBADO"))) -> REPROBADO | CX21: 10 | CY21: =B21 | CZ21: =C21 -> Cedeño Sanchez Josué | DA21: =CS21 -> 4.67 | DC21: =IF(DA21>=7,DA21,IF(DA21="","",IF(DB21="",AVERAGE(DA21:DB21),IF(AND(DA21<4.01,DB21<>""),DA21,IF(DB21<7,DA21,7))))) -> 4.67 | DD21: =IF(AND(DA21>=7,DB21<>""),"DEJE EN BLANCO EL CASILLERO SUPLETORIO",IF(DA21="","",IF(AND(DA21<5,DB21<>""),"NO PUEDE RENDIR SUPLETORIO;REPRUEBA EL GRADO",IF(DC21<7,"NO PROMOVIDO","PROMOVIDO")))) -> NO PROMOVIDO
A22: 11 | B22: ='PROY. INTER'!B22 | C22: ='PROY. INTER'!C22 -> Espinoza Martinez Stefano Juliano | D22: 10 | H22: 10 | N22: 10 | P22: 10 | V22: =IFERROR(TRUNC(AVERAGE(D22:U22),2),"")*70/100 -> 7 | W22: 10 | X22: ='PROY. INTER'!W22 -> 10 | Y22: =AVERAGE(W22:X22) -> 10 | Z22: =Y22*30/100 -> 3 | AA22: =IFERROR(TRUNC(SUM(V22+Z22),2),"") -> 10 | AE22: 11 | AF22: =B22 | AG22: =C22 -> Espinoza Martinez Stefano Juliano | AH22: 10 | AL22: 10 | AR22: 10 | AT22: 10 | AZ22: =IFERROR(TRUNC(AVERAGE(AH22:AY22),2),"")*70/100 -> 7 | BA22: 10 | BB22: ='PROY. INTER'!AX22 -> 10 | BC22: =AVERAGE(BA22:BB22) -> 10 | BD22: =BC22*30/100 -> 3 | BE22: =IFERROR(TRUNC(SUM(AZ22+BD22),2),"") -> 10 | BI22: 11 | BJ22: =B22 | BK22: =C22 -> Espinoza Martinez Stefano Juliano | CD22: =IFERROR(TRUNC(AVERAGE(BL22:CC22),2),"")*70/100 -> 0 | CF22: ='PROY. INTER'!BY22 -> 0 | CG22: =AVERAGE(CE22:CF22) -> 0 | CH22: =CG22*30/100 -> 0 | CI22: =IFERROR(TRUNC(SUM(CD22+CH22),2),"") -> 0 | CM22: 11 | CN22: =B22 | CO22: =C22 -> Espinoza Martinez Stefano Juliano | CP22: =AA22 -> 10 | CQ22: =BE22 -> 10 | CR22: =CI22 -> 0 | CS22: =IFERROR(TRUNC(AVERAGE(CP22:CR22),2),"")*100/100 -> 6.66 | CT22: =IF(CS22="","",IF(CS22>=7,"APROBADO",IF(AND(CS22<=6.99,CS22>=5),"SUPLETORIO","REPROBADO"))) -> SUPLETORIO | CX22: 11 | CY22: =B22 | CZ22: =C22 -> Espinoza Martinez Stefano Juliano | DA22: =CS22 -> 6.66 | DC22: =IF(DA22>=7,DA22,IF(DA22="","",IF(DB22="",AVERAGE(DA22:DB22),IF(AND(DA22<4.01,DB22<>""),DA22,IF(DB22<7,DA22,7))))) -> 6.66 | DD22: =IF(AND(DA22>=7,DB22<>""),"DEJE EN BLANCO EL CASILLERO SUPLETORIO",IF(DA22="","",IF(AND(DA22<5,DB22<>""),"NO PUEDE RENDIR SUPLETORIO;REPRUEBA EL GRADO",IF(DC22<7,"NO PROMOVIDO","PROMOVIDO")))) -> NO PROMOVIDO
A23: 12 | B23: ='PROY. INTER'!B23 | C23: ='PROY. INTER'!C23 -> Espinoza Morante Melany Ginger | D23: 10 | H23: 10 | N23: 8 | P23: 10 | V23: =IFERROR(TRUNC(AVERAGE(D23:U23),2),"")*70/100 -> 6.65 | W23: 10 | X23: ='PROY. INTER'!W23 -> 7.2 | Y23: =AVERAGE(W23:X23) -> 8.6 | Z23: =Y23*30/100 -> 2.58 | AA23: =IFERROR(TRUNC(SUM(V23+Z23),2),"") -> 9.23 | AE23: 12 | AF23: =B23 | AG23: =C23 -> Espinoza Morante Melany Ginger | AH23: 10 | AL23: 10 | AR23: 9 | AT23: 9 | AZ23: =IFERROR(TRUNC(AVERAGE(AH23:AY23),2),"")*70/100 -> 6.65 | BA23: 10 | BB23: ='PROY. INTER'!AX23 -> 10 | BC23: =AVERAGE(BA23:BB23) -> 10 | BD23: =BC23*30/100 -> 3 | BE23: =IFERROR(TRUNC(SUM(AZ23+BD23),2),"") -> 9.65 | BI23: 12 | BJ23: =B23 | BK23: =C23 -> Espinoza Morante Melany Ginger | CD23: =IFERROR(TRUNC(AVERAGE(BL23:CC23),2),"")*70/100 -> 0 | CF23: ='PROY. INTER'!BY23 -> 0 | CG23: =AVERAGE(CE23:CF23) -> 0 | CH23: =CG23*30/100 -> 0 | CI23: =IFERROR(TRUNC(SUM(CD23+CH23),2),"") -> 0 | CM23: 12 | CN23: =B23 | CO23: =C23 -> Espinoza Morante Melany Ginger | CP23: =AA23 -> 9.23 | CQ23: =BE23 -> 9.65 | CR23: =CI23 -> 0 | CS23: =IFERROR(TRUNC(AVERAGE(CP23:CR23),2),"")*100/100 -> 6.29 | CT23: =IF(CS23="","",IF(CS23>=7,"APROBADO",IF(AND(CS23<=6.99,CS23>=5),"SUPLETORIO","REPROBADO"))) -> SUPLETORIO | CX23: 12 | CY23: =B23 | CZ23: =C23 -> Espinoza Morante Melany Ginger | DA23: =CS23 -> 6.29 | DC23: =IF(DA23>=7,DA23,IF(DA23="","",IF(DB23="",AVERAGE(DA23:DB23),IF(AND(DA23<4.01,DB23<>""),DA23,IF(DB23<7,DA23,7))))) -> 6.29 | DD23: =IF(AND(DA23>=7,DB23<>""),"DEJE EN BLANCO EL CASILLERO SUPLETORIO",IF(DA23="","",IF(AND(DA23<5,DB23<>""),"NO PUEDE RENDIR SUPLETORIO;REPRUEBA EL GRADO",IF(DC23<7,"NO PROMOVIDO","PROMOVIDO")))) -> NO PROMOVIDO
... A35: 24 | B35: ='PROY. INTER'!B35 | C35: ='PROY. INTER'!C35 -> Zambrano Zhicay Victor Humberto | D35: 10 | H35: 10 | N35: 9 | P35: 9.5 | V35: =IFERROR(TRUNC(AVERAGE(D35:U35),2),"")*70/100 -> 6.734 | W35: 10 | X35: ='PROY. INTER'!W35 -> 9.73 | Y35: =AVERAGE(W35:X35) -> 9.865 | Z35: =Y35*30/100 -> 2.9595 | AA35: =IFERROR(TRUNC(SUM(V35+Z35),2),"") -> 9.69 | AE35: 24 | AF35: =B35 | AG35: =C35 -> Zambrano Zhicay Victor Humberto | AH35: 8 | AL35: 9 | AR35: 8 | AT35: 8.5 | AZ35: =IFERROR(TRUNC(AVERAGE(AH35:AY35),2),"")*70/100 -> 5.859 | BA35: 8 | BB35: ='PROY. INTER'!AX35 -> 10 | BC35: =AVERAGE(BA35:BB35) -> 9 | BD35: =BC35*30/100 -> 2.7 | BE35: =IFERROR(TRUNC(SUM(AZ35+BD35),2),"") -> 8.55 | BI35: 24 | BJ35: =B35 | BK35: =C35 -> Zambrano Zhicay Victor Humberto | CD35: =IFERROR(TRUNC(AVERAGE(BL35:CC35),2),"")*70/100 -> 0 | CF35: ='PROY. INTER'!BY35 -> 0 | CG35: =AVERAGE(CE35:CF35) -> 0 | CH35: =CG35*30/100 -> 0 | CI35: =IFERROR(TRUNC(SUM(CD35+CH35),2),"") -> 0 | CM35: 24 | CN35: =B35 | CO35: =C35 -> Zambrano Zhicay Victor Humberto | CP35: =AA35 -> 9.69 | CQ35: =BE35 -> 8.55 | CR35: =CI35 -> 0 | CS35: =IFERROR(TRUNC(AVERAGE(CP35:CR35),2),"")*100/100 -> 6.08 | CT35: =IF(CS35="","",IF(CS35>=7,"APROBADO",IF(AND(CS35<=6.99,CS35>=5),"SUPLETORIO","REPROBADO"))) -> SUPLETORIO | CX35: 24 | CY35: =B35 | CZ35: =C35 -> Zambrano Zhicay Victor Humberto | DA35: =CS35 -> 6.08 | DC35: =IF(DA35>=7,DA35,IF(DA35="","",IF(DB35="",AVERAGE(DA35:DB35),IF(AND(DA35<4.01,DB35<>""),DA35,IF(DB35<7,DA35,7))))) -> 6.08 | DD35: =IF(AND(DA35>=7,DB35<>""),"DEJE EN BLANCO EL CASILLERO SUPLETORIO",IF(DA35="","",IF(AND(DA35<5,DB35<>""),"NO PUEDE RENDIR SUPLETORIO;REPRUEBA EL GRADO",IF(DC35<7,"NO PROMOVIDO","PROMOVIDO")))) -> NO PROMOVIDO
A36: 25 | B36: ='PROY. INTER'!B36 | C36: ='PROY. INTER'!C36 | V36: =IFERROR(TRUNC(AVERAGE(D36:U36),2),"")*70/100 -> 0 | X36: ='PROY. INTER'!W36 -> 0 | Y36: =AVERAGE(W36:X36) -> 0 | Z36: =Y36*30/100 -> 0 | AA36: =IFERROR(TRUNC(SUM(V36+Z36),2),"") -> 0 | AE36: 25 | AF36: =B36 | AG36: =C36 | AZ36: =IFERROR(TRUNC(AVERAGE(AH36:AY36),2),"")*70/100 -> 0 | BB36: ='PROY. INTER'!AX36 -> 0 | BC36: =AVERAGE(BA36:BB36) -> 0 | BD36: =BC36*30/100 -> 0 | BE36: =IFERROR(TRUNC(SUM(AZ36+BD36),2),"") -> 0 | BI36: 25 | BJ36: =B36 | BK36: =C36 | CD36: =IFERROR(TRUNC(AVERAGE(BL36:CC36),2),"")*70/100 -> 0 | CF36: ='PROY. INTER'!BY36 -> 0 | CG36: =AVERAGE(CE36:CF36) -> 0 | CH36: =CG36*30/100 -> 0 | CI36: =IFERROR(TRUNC(SUM(CD36+CH36),2),"") -> 0 | CM36: 25 | CN36: =B36 | CO36: =C36 | CP36: =AA36 -> 0 | CQ36: =BE36 -> 0 | CR36: =CI36 -> 0 | CS36: =IFERROR(TRUNC(AVERAGE(CP36:CR36),2),"")*100/100 -> 0 | CT36: =IF(CS36="","",IF(CS36>=7,"APROBADO",IF(AND(CS36<=6.99,CS36>=5),"SUPLETORIO","REPROBADO"))) -> REPROBADO | CX36: 25 | CY36: =B36 | CZ36: =C36 | DA36: =CS36 -> 0 | DC36: =IF(DA36>=7,DA36,IF(DA36="","",IF(DB36="",AVERAGE(DA36:DB36),IF(AND(DA36<4.01,DB36<>""),DA36,IF(DB36<7,DA36,7))))) -> 0 | DD36: =IF(AND(DA36>=7,DB36<>""),"DEJE EN BLANCO EL CASILLERO SUPLETORIO",IF(DA36="","",IF(AND(DA36<5,DB36<>""),"NO PUEDE RENDIR SUPLETORIO;REPRUEBA EL GRADO",IF(DC36<7,"NO PROMOVIDO","PROMOVIDO")))) -> NO PROMOVIDO
